Workbook

Sheet Recap Freelance 2026
A1: Recap 2026
A3: Prime perçue
A4: Matricule_Perçoit_Prime | B4: T1 | D4: T2 | F4: T3 | H4: T4 | J4: Total général
B5: Prime | C5: =HYPERLINK("https://drive.google.com/open?id=1jG2WnssbXfPpy5PXQYAraR2E-vZUA_T7ymWXxeFUIhs" , "Bénéfice LL") -> Bénéfice LL | D5: Prime | E5: =HYPERLINK("https://drive.google.com/open?id=1jMvgM0QVdQctDXGBCk1x_WX0RSF3pQzmD4ZfjTL1usM" , "Bénéfice LL") -> Bénéfice LL | F5: Prime | G5: =HYPERLINK("https://docs.google.com/spreadsheets/d/1EGxWOQCyfE9qIur-uKavwV3ESGa7BGtdSxpvnM4Nzu0/edit#gid=522824772" , "Bénéfice LL") -> Bénéfice LL | H5: Prime | I5: =HYPERLINK("https://docs.google.com/spreadsheets/d/1D9lzs32aLilQQZ-3jVFKPa_dpoNGu5nn_RDx7SMvfdU/edit?usp=sharing&ouid=106178672536291372263&rtpof=true&sd=true" , "Bénéfice LL") -> Bénéfice LL | J5: Prime | K5: Bénéfice LL | M5: Prime
A6: ADO | B6: =IF(ISNA(VLOOKUP($A6,'Prime Freelance T1 2026'!$A$3:$F$42,5,FALSE)),0,VLOOKUP($A6,'Prime Freelance T1 2026'!$A$3:$F$42,5,FALSE)) -> 1963 | D6: =IF(ISNA(VLOOKUP(A6,'Prime Freelance T2 2026'!$A$3:$H$38,6,FALSE)),0,VLOOKUP(A6,'Prime Freelance T2 2026'!$A$3:$H$38,6,FALSE)) -> 5761.25 | F6: =IF(ISNA(VLOOKUP(A6,'Prime Freelance T3 2026'!$A$3:$E$32,5,FALSE)),0,VLOOKUP(A6,'Prime Freelance T3 2026'!$A$3:$E$32,5,FALSE)) -> 0 | H6: =IF(ISNA(VLOOKUP(A6,'Prime Freelance T4 2026'!$A$4:$F$36,4,FALSE)),0,VLOOKUP(A6,'Prime Freelance T4 2026'!$A$4:$F$36,4,FALSE)) -> 0 | J6: =B6+D6+F6+H6 -> 7724.25 | K6: =C6+E6+G6+I6 -> 0
A7: AMA | B7: =IF(ISNA(VLOOKUP($A7,'Prime Freelance T1 2026'!$A$3:$F$42,5,FALSE)),0,VLOOKUP($A7,'Prime Freelance T1 2026'!$A$3:$F$42,5,FALSE)) -> 40437.1 | D7: =IF(ISNA(VLOOKUP(A7,'Prime Freelance T2 2026'!$A$3:$H$38,6,FALSE)),0,VLOOKUP(A7,'Prime Freelance T2 2026'!$A$3:$H$38,6,FALSE)) -> 40695.98 | F7: =IF(ISNA(VLOOKUP(A7,'Prime Freelance T3 2026'!$A$3:$E$32,5,FALSE)),0,VLOOKUP(A7,'Prime Freelance T3 2026'!$A$3:$E$32,5,FALSE)) -> 0 | H7: =IF(ISNA(VLOOKUP(A7,'Prime Freelance T4 2026'!$A$4:$F$36,4,FALSE)),0,VLOOKUP(A7,'Prime Freelance T4 2026'!$A$4:$F$36,4,FALSE)) -> 0 | J7: =B7+D7+F7+H7 -> 81133.08 | K7: =C7+E7+G7+I7 -> 0
A8: AMO | B8: =IF(ISNA(VLOOKUP($A8,'Prime Freelance T1 2026'!$A$3:$F$42,5,FALSE)),0,VLOOKUP($A8,'Prime Freelance T1 2026'!$A$3:$F$42,5,FALSE)) -> 13375.3 | D8: =IF(ISNA(VLOOKUP(A8,'Prime Freelance T2 2026'!$A$3:$H$38,6,FALSE)),0,VLOOKUP(A8,'Prime Freelance T2 2026'!$A$3:$H$38,6,FALSE)) -> 11701.75 | F8: =IF(ISNA(VLOOKUP(A8,'Prime Freelance T3 2026'!$A$3:$E$32,5,FALSE)),0,VLOOKUP(A8,'Prime Freelance T3 2026'!$A$3:$E$32,5,FALSE)) -> 0 | H8: =IF(ISNA(VLOOKUP(A8,'Prime Freelance T4 2026'!$A$4:$F$36,4,FALSE)),0,VLOOKUP(A8,'Prime Freelance T4 2026'!$A$4:$F$36,4,FALSE)) -> 0 | J8: =B8+D8+F8+H8 -> 25077.05 | K8: =C8+E8+G8+I8 -> 0
A9: CCO | B9: =IF(ISNA(VLOOKUP($A9,'Prime Freelance T1 2026'!$A$3:$F$42,5,FALSE)),0,VLOOKUP($A9,'Prime Freelance T1 2026'!$A$3:$F$42,5,FALSE)) -> 915 | D9: =IF(ISNA(VLOOKUP(A9,'Prime Freelance T2 2026'!$A$3:$H$38,6,FALSE)),0,VLOOKUP(A9,'Prime Freelance T2 2026'!$A$3:$H$38,6,FALSE)) -> 825 | F9: =IF(ISNA(VLOOKUP(A9,'Prime Freelance T3 2026'!$A$3:$E$32,5,FALSE)),0,VLOOKUP(A9,'Prime Freelance T3 2026'!$A$3:$E$32,5,FALSE)) -> 0 | H9: =IF(ISNA(VLOOKUP(A9,'Prime Freelance T4 2026'!$A$4:$F$36,4,FALSE)),0,VLOOKUP(A9,'Prime Freelance T4 2026'!$A$4:$F$36,4,FALSE)) -> 0 | J9: =B9+D9+F9+H9 -> 1740 | K9: =C9+E9+G9+I9 -> 0
A10: DMA | B10: =IF(ISNA(VLOOKUP($A10,'Prime Freelance T1 2026'!$A$3:$F$42,5,FALSE)),0,VLOOKUP($A10,'Prime Freelance T1 2026'!$A$3:$F$42,5,FALSE)) -> 1160 | D10: =IF(ISNA(VLOOKUP(A10,'Prime Freelance T2 2026'!$A$3:$H$38,6,FALSE)),0,VLOOKUP(A10,'Prime Freelance T2 2026'!$A$3:$H$38,6,FALSE)) -> 910 | F10: =IF(ISNA(VLOOKUP(A10,'Prime Freelance T3 2026'!$A$3:$E$32,5,FALSE)),0,VLOOKUP(A10,'Prime Freelance T3 2026'!$A$3:$E$32,5,FALSE)) -> 0 | H10: =IF(ISNA(VLOOKUP(A10,'Prime Freelance T4 2026'!$A$4:$F$36,4,FALSE)),0,VLOOKUP(A10,'Prime Freelance T4 2026'!$A$4:$F$36,4,FALSE)) -> 0 | J10: =B10+D10+F10+H10 -> 2070 | K10: =C10+E10+G10+I10 -> 0
A11: DZE | B11: =IF(ISNA(VLOOKUP($A11,'Prime Freelance T1 2026'!$A$3:$F$42,5,FALSE)),0,VLOOKUP($A11,'Prime Freelance T1 2026'!$A$3:$F$42,5,FALSE)) -> 2439.09 | D11: =IF(ISNA(VLOOKUP(A11,'Prime Freelance T2 2026'!$A$3:$H$38,6,FALSE)),0,VLOOKUP(A11,'Prime Freelance T2 2026'!$A$3:$H$38,6,FALSE)) -> 1672.95 | F11: =IF(ISNA(VLOOKUP(A11,'Prime Freelance T3 2026'!$A$3:$E$32,5,FALSE)),0,VLOOKUP(A11,'Prime Freelance T3 2026'!$A$3:$E$32,5,FALSE)) -> 0 | H11: =IF(ISNA(VLOOKUP(A11,'Prime Freelance T4 2026'!$A$4:$F$36,4,FALSE)),0,VLOOKUP(A11,'Prime Freelance T4 2026'!$A$4:$F$36,4,FALSE)) -> 0 | J11: =B11+D11+F11+H11 -> 4112.04 | K11: =C11+E11+G11+I11 -> 0
A12: GBO | B12: =IF(ISNA(VLOOKUP($A12,'Prime Freelance T1 2026'!$A$3:$F$42,5,FALSE)),0,VLOOKUP($A12,'Prime Freelance T1 2026'!$A$3:$F$42,5,FALSE)) -> 9714.8 | D12: =IF(ISNA(VLOOKUP(A12,'Prime Freelance T2 2026'!$A$3:$H$38,6,FALSE)),0,VLOOKUP(A12,'Prime Freelance T2 2026'!$A$3:$H$38,6,FALSE)) -> 8831.99 | F12: =IF(ISNA(VLOOKUP(A12,'Prime Freelance T3 2026'!$A$3:$E$32,5,FALSE)),0,VLOOKUP(A12,'Prime Freelance T3 2026'!$A$3:$E$32,5,FALSE)) -> 0 | H12: =IF(ISNA(VLOOKUP(A12,'Prime Freelance T4 2026'!$A$4:$F$36,4,FALSE)),0,VLOOKUP(A12,'Prime Freelance T4 2026'!$A$4:$F$36,4,FALSE)) -> 0 | J12: =B12+D12+F12+H12 -> 18546.79 | K12: =C12+E12+G12+I12 -> 0
A13: GLA | B13: =IF(ISNA(VLOOKUP($A13,'Prime Freelance T1 2026'!$A$3:$F$42,5,FALSE)),0,VLOOKUP($A13,'Prime Freelance T1 2026'!$A$3:$F$42,5,FALSE)) -> 507.6 | D13: =IF(ISNA(VLOOKUP(A13,'Prime Freelance T2 2026'!$A$3:$H$38,6,FALSE)),0,VLOOKUP(A13,'Prime Freelance T2 2026'!$A$3:$H$38,6,FALSE)) -> 399.6 | F13: =IF(ISNA(VLOOKUP(A13,'Prime Freelance T3 2026'!$A$3:$E$32,5,FALSE)),0,VLOOKUP(A13,'Prime Freelance T3 2026'!$A$3:$E$32,5,FALSE)) -> 0 | H13: =IF(ISNA(VLOOKUP(A13,'Prime Freelance T4 2026'!$A$4:$F$36,4,FALSE)),0,VLOOKUP(A13,'Prime Freelance T4 2026'!$A$4:$F$36,4,FALSE)) -> 0 | J13: =B13+D13+F13+H13 -> 907.2 | K13: =C13+E13+G13+I13 -> 0
A14: GME | B14: =IF(ISNA(VLOOKUP($A14,'Prime Freelance T1 2026'!$A$3:$F$42,5,FALSE)),0,VLOOKUP($A14,'Prime Freelance T1 2026'!$A$3:$F$42,5,FALSE)) -> 1669.75 | D14: =IF(ISNA(VLOOKUP(A14,'Prime Freelance T2 2026'!$A$3:$H$38,6,FALSE)),0,VLOOKUP(A14,'Prime Freelance T2 2026'!$A$3:$H$38,6,FALSE)) -> 863.89 | F14: =IF(ISNA(VLOOKUP(A14,'Prime Freelance T3 2026'!$A$3:$E$32,5,FALSE)),0,VLOOKUP(A14,'Prime Freelance T3 2026'!$A$3:$E$32,5,FALSE)) -> 0 | H14: =IF(ISNA(VLOOKUP(A14,'Prime Freelance T4 2026'!$A$4:$F$36,4,FALSE)),0,VLOOKUP(A14,'Prime Freelance T4 2026'!$A$4:$F$36,4,FALSE)) -> 0 | J14: =B14+D14+F14+H14 -> 2533.64 | K14: =C14+E14+G14+I14 -> 0
A15: HZO | B15: =IF(ISNA(VLOOKUP($A15,'Prime Freelance T1 2026'!$A$3:$F$42,5,FALSE)),0,VLOOKUP($A15,'Prime Freelance T1 2026'!$A$3:$F$42,5,FALSE)) -> 11905.55 | D15: =IF(ISNA(VLOOKUP(A15,'Prime Freelance T2 2026'!$A$3:$H$38,6,FALSE)),0,VLOOKUP(A15,'Prime Freelance T2 2026'!$A$3:$H$38,6,FALSE)) -> 15470 | F15: =IF(ISNA(VLOOKUP(A15,'Prime Freelance T3 2026'!$A$3:$E$32,5,FALSE)),0,VLOOKUP(A15,'Prime Freelance T3 2026'!$A$3:$E$32,5,FALSE)) -> 0 | H15: =IF(ISNA(VLOOKUP(A15,'Prime Freelance T4 2026'!$A$4:$F$36,4,FALSE)),0,VLOOKUP(A15,'Prime Freelance T4 2026'!$A$4:$F$36,4,FALSE)) -> 0 | J15: =B15+D15+F15+H15 -> 27375.55 | K15: =C15+E15+G15+I15 -> 0
A16: IAB | B16: =IF(ISNA(VLOOKUP($A16,'Prime Freelance T1 2026'!$A$3:$F$42,5,FALSE)),0,VLOOKUP($A16,'Prime Freelance T1 2026'!$A$3:$F$42,5,FALSE)) -> 290 | D16: =IF(ISNA(VLOOKUP(A16,'Prime Freelance T2 2026'!$A$3:$H$38,6,FALSE)),0,VLOOKUP(A16,'Prime Freelance T2 2026'!$A$3:$H$38,6,FALSE)) -> 0 | F16: =IF(ISNA(VLOOKUP(A16,'Prime Freelance T3 2026'!$A$3:$E$32,5,FALSE)),0,VLOOKUP(A16,'Prime Freelance T3 2026'!$A$3:$E$32,5,FALSE)) -> 0 | H16: =IF(ISNA(VLOOKUP(A16,'Prime Freelance T4 2026'!$A$4:$F$36,4,FALSE)),0,VLOOKUP(A16,'Prime Freelance T4 2026'!$A$4:$F$36,4,FALSE)) -> 0 | J16: =B16+D16+F16+H16 -> 290 | K16: =C16+E16+G16+I16 -> 0
A17: JBO | B17: =IF(ISNA(VLOOKUP($A17,'Prime Freelance T1 2026'!$A$3:$F$42,5,FALSE)),0,VLOOKUP($A17,'Prime Freelance T1 2026'!$A$3:$F$42,5,FALSE)) -> 22421.22 | D17: =IF(ISNA(VLOOKUP(A17,'Prime Freelance T2 2026'!$A$3:$H$38,6,FALSE)),0,VLOOKUP(A17,'Prime Freelance T2 2026'!$A$3:$H$38,6,FALSE)) -> 27005.67 | F17: =IF(ISNA(VLOOKUP(A17,'Prime Freelance T3 2026'!$A$3:$E$32,5,FALSE)),0,VLOOKUP(A17,'Prime Freelance T3 2026'!$A$3:$E$32,5,FALSE)) -> 0 | H17: =IF(ISNA(VLOOKUP(A17,'Prime Freelance T4 2026'!$A$4:$F$36,4,FALSE)),0,VLOOKUP(A17,'Prime Freelance T4 2026'!$A$4:$F$36,4,FALSE)) -> 0 | J17: =B17+D17+F17+H17 -> 49426.89 | K17: =C17+E17+G17+I17 -> 0
... A36: YMA | B36: =IF(ISNA(VLOOKUP($A36,'Prime Freelance T1 2026'!$A$3:$F$42,5,FALSE)),0,VLOOKUP($A36,'Prime Freelance T1 2026'!$A$3:$F$42,5,FALSE)) -> 1008 | D36: =IF(ISNA(VLOOKUP(A36,'Prime Freelance T2 2026'!$A$3:$H$38,6,FALSE)),0,VLOOKUP(A36,'Prime Freelance T2 2026'!$A$3:$H$38,6,FALSE)) -> 1008 | F36: =IF(ISNA(VLOOKUP(A36,'Prime Freelance T3 2026'!$A$3:$E$32,5,FALSE)),0,VLOOKUP(A36,'Prime Freelance T3 2026'!$A$3:$E$32,5,FALSE)) -> 0 | H36: =IF(ISNA(VLOOKUP(A36,'Prime Freelance T4 2026'!$A$4:$F$36,4,FALSE)),0,VLOOKUP(A36,'Prime Freelance T4 2026'!$A$4:$F$36,4,FALSE)) -> 0 | J36: =B36+D36+F36+H36 -> 2016 | K36: =C36+E36+G36+I36 -> 0
B37: =IF(ISNA(VLOOKUP($A37,'Prime Freelance T1 2026'!$A$3:$F$42,5,FALSE)),0,VLOOKUP($A37,'Prime Freelance T1 2026'!$A$3:$F$42,5,FALSE)) -> 0 | D37: =IF(ISNA(VLOOKUP(A37,'Prime Freelance T2 2026'!$A$3:$H$38,6,FALSE)),0,VLOOKUP(A37,'Prime Freelance T2 2026'!$A$3:$H$38,6,FALSE)) -> 0 | F37: =IF(ISNA(VLOOKUP(A37,'Prime Freelance T3 2026'!$A$3:$E$32,5,FALSE)),0,VLOOKUP(A37,'Prime Freelance T3 2026'!$A$3:$E$32,5,FALSE)) -> 0 | H37: =IF(ISNA(VLOOKUP(A37,'Prime Freelance T4 2026'!$A$4:$F$36,4,FALSE)),0,VLOOKUP(A37,'Prime Freelance T4 2026'!$A$4:$F$36,4,FALSE)) -> 0 | J37: =B37+D37+F37+H37 -> 0 | K37: =C37+E37+G37+I37 -> 0
B38: =IF(ISNA(VLOOKUP($A38,'Prime Freelance T1 2026'!$A$3:$F$42,5,FALSE)),0,VLOOKUP($A38,'Prime Freelance T1 2026'!$A$3:$F$42,5,FALSE)) -> 0 | D38: =IF(ISNA(VLOOKUP(A38,'Prime Freelance T2 2026'!$A$3:$H$38,6,FALSE)),0,VLOOKUP(A38,'Prime Freelance T2 2026'!$A$3:$H$38,6,FALSE)) -> 0 | F38: =IF(ISNA(VLOOKUP(A38,'Prime Freelance T3 2026'!$A$3:$E$32,5,FALSE)),0,VLOOKUP(A38,'Prime Freelance T3 2026'!$A$3:$E$32,5,FALSE)) -> 0 | H38: =IF(ISNA(VLOOKUP(A38,'Prime Freelance T4 2026'!$A$4:$F$36,4,FALSE)),0,VLOOKUP(A38,'Prime Freelance T4 2026'!$A$4:$F$36,4,FALSE)) -> 0 | J38: =B38+D38+F38+H38 -> 0 | K38: =C38+E38+G38+I38 -> 0
B39: =IF(ISNA(VLOOKUP($A39,'Prime Freelance T1 2026'!$A$3:$F$42,5,FALSE)),0,VLOOKUP($A39,'Prime Freelance T1 2026'!$A$3:$F$42,5,FALSE)) -> 0 | D39: =IF(ISNA(VLOOKUP(A39,'Prime Freelance T2 2026'!$A$3:$H$38,6,FALSE)),0,VLOOKUP(A39,'Prime Freelance T2 2026'!$A$3:$H$38,6,FALSE)) -> 0 | F39: =IF(ISNA(VLOOKUP(A39,'Prime Freelance T3 2026'!$A$3:$E$32,5,FALSE)),0,VLOOKUP(A39,'Prime Freelance T3 2026'!$A$3:$E$32,5,FALSE)) -> 0 | H39: =IF(ISNA(VLOOKUP(A39,'Prime Freelance T4 2026'!$A$4:$F$36,4,FALSE)),0,VLOOKUP(A39,'Prime Freelance T4 2026'!$A$4:$F$36,4,FALSE)) -> 0 | J39: =B39+D39+F39+H39 -> 0 | K39: =C39+E39+G39+I39 -> 0
A40: Total général | B40: =SUM(B6:B39) -> 152559.29 | C40: =SUM(C7:C39) -> 0 | D40: =SUM(D6:D39) -> 157149.51 | E40: =SUM(E7:E39) -> 0 | F40: =SUM(F6:F39) -> 0 | G40: =SUM(G7:G39) -> 0 | H40: =SUM(H6:H39) -> 0 | I40: =SUM(I7:I39) -> 0 | J40: =B40+D40+F40+H40 -> 309708.8 | K40: =C40+E40+G40+I40 -> 0

Sheet Prime Freelance T1 2026
A1: Montant des primes freelance pour le T1 2026
A3: Matricule_Perçoit_Prime | B3: Prime commerciale freelance | C3: Prime encadrement | D3: Corrections | E3: Total général
A4: ADO | B4: 1093 | C4: 870 | E4: =SUM(B4:D4) -> 1963
A5: AMA | B5: 39789.1 | C5: 1160 | D5: -512 | E5: =SUM(B5:D5) -> 40437.1
A6: AMO | B6: 12505.3 | C6: 870 | E6: =SUM(B6:D6) -> 13375.3
A7: CCO | B7: 915 | E7: =SUM(B7:D7) -> 915
A8: DMA | B8: 1160 | E8: =SUM(B8:D8) -> 1160
A9: DZE | B9: 2439.09 | E9: =SUM(B9:D9) -> 2439.09
A10: GBO | B10: 8844.8 | C10: 870 | E10: =SUM(B10:D10) -> 9714.8
A11: GLA | B11: 507.6 | E11: =SUM(B11:D11) -> 507.6
A12: GME | B12: 1669.75 | E12: =SUM(B12:D12) -> 1669.75
A13: HZO | B13: 11905.55 | E13: =SUM(B13:D13) -> 11905.55
A14: IAB | C14: 290 | E14: =SUM(B14:D14) -> 290
A15: JBO | B15: 21603 | C15: 818.22 | E15: =SUM(B15:D15) -> 22421.22
A16: JHU | B16: 44.7 | E16: =SUM(B16:D16) -> 44.7
A17: JMM | C17: 739.03 | E17: =SUM(B17:D17) -> 739.03
A18: KML | B18: 12078.8 | C18: 1740 | E18: =SUM(B18:D18) -> 13818.8
A19: MAU | B19: 882 | E19: =SUM(B19:D19) -> 882
A20: MBO | B20: 2064 | C20: 870 | E20: =SUM(B20:D20) -> 2934
A21: MMO | B21: 2856.8 | E21: =SUM(B21:D21) -> 2856.8
A22: MNA | B22: 11212.35 | E22: =SUM(B22:D22) -> 11212.35
A23: NSA | C23: 168.39 | E23: =SUM(B23:D23) -> 168.39
A24: NVB | B24: 702.7 | E24: =SUM(B24:D24) -> 702.7
A25: OHI | B25: 928 | E25: =SUM(B25:D25) -> 928
A26: OLA | B26: 620 | E26: =SUM(B26:D26) -> 620
A27: PLT | B27: 243.2 | C27: 290 | E27: =SUM(B27:D27) -> 533.2
A28: SAD | B28: 820.2 | E28: =SUM(B28:D28) -> 820.2
A29: SAT | B29: 1376.95 | C29: 692.26 | D29: 512 | E29: =SUM(B29:D29) -> 2581.21
A30: SEJ | B30: 2398.45 | E30: =SUM(B30:D30) -> 2398.45
A31: SNA | B31: 708 | E31: =SUM(B31:D31) -> 708
A32: SSA | B32: 663 | E32: =SUM(B32:D32) -> 663
A33: VRI | B33: 2142.05 | E33: =SUM(B33:D33) -> 2142.05
A34: YMA | B34: 1008 | E34: =SUM(B34:D34) -> 1008
A35: Total général | B35: =SUM(B4:B34) -> 143181.39 | C35: =SUM(C4:C34) -> 9377.9 | D35: =SUM(D4:D34) -> 0 | E35: =SUM(E4:E34) -> 152559.29
A41: Annee | B41: Mois | C41: Projet | D41: Matricule_Consultant_Place | E41: Matricule_Percoit_Prime | F41: Type_Prime | G41: Nb_Jour | H41: Montant_Journalier_Cout_LL | I41: Montant_Mensuel_Cout_LL
A42: 2026 | B42: 1 | C42: ABB - Pilote POA - SUEZ | D42: ABB | E42: JBO | F42: Commerciale freelance | G42: 16 | H42: 12.5 | I42: 200
A43: 2026 | B43: 2 | C43: ABB - Pilote POA - SUEZ | D43: ABB | E43: JBO | F43: Commerciale freelance | G43: 17.5 | H43: 12.5 | I43: 218.75
A44: 2026 | B44: 3 | C44: ABB - Pilote POA - SUEZ | D44: ABB | E44: JBO | F44: Commerciale freelance | G44: 20.5 | H44: 12.5 | I44: 256.25
A45: 2026 | B45: 1 | C45: Dispositif PO - TotalEnergies | D45: ABT | E45: AMA | F45: Commerciale freelance | G45: 17 | H45: 25.5 | I45: 433.5
A46: 2026 | B46: 1 | C46: Dispositif PO - TotalEnergies | D46: ABT | E46: MNA | F46: Commerciale freelance | G46: 17 | H46: 5.9 | I46: 100.3
...

Sheet Prime Freelance T2 2026
A1: Montant des primes freelance pour le T2 2026
A3: Matricule_Perçoit_Prime | B3: Prime commerciale freelance | C3: Prime encadrement | D3: Recrutement | E3: Correction Prime T1 | F3: Total général
A4: ADO | B4: 3151.25 | C4: 2610 | F4: =SUM(B4:D4) -> 5761.25
A5: AMA | B5: 40695.98 | F5: =SUM(B5:D5) -> 40695.98
A6: AMO | B6: 10831.75 | C6: 870 | F6: =SUM(B6:D6) -> 11701.75
A7: CCO | B7: 825 | F7: =SUM(B7:D7) -> 825
A8: DMA | B8: 910 | F8: =SUM(B8:D8) -> 910
A9: DZE | B9: 1672.95 | F9: =SUM(B9:D9) -> 1672.95
A10: GBO | B10: 7584.99 | C10: 1247 | F10: =SUM(B10:D10) -> 8831.99
A11: GLA | B11: 399.6 | F11: =SUM(B11:D11) -> 399.6
A12: GME | B12: 863.89 | F12: =SUM(B12:D12) -> 863.89
A13: HZO | B13: 15470 | F13: =SUM(B13:D13) -> 15470
A14: JBO | B14: 25024 | C14: 1981.67 | F14: =SUM(B14:D14) -> 27005.67
A15: JHU | B15: 223.5 | F15: =SUM(B15:D15) -> 223.5
A16: JMM | C16: 947.33 | F16: =SUM(B16:D16) -> 947.33
A17: KML | B17: 11897.95 | C17: 1740 | F17: =SUM(B17:D17) -> 13637.95
A18: MAU | B18: 220.5 | F18: =SUM(B18:D18) -> 220.5
A19: MBO | B19: 1548 | C19: 551.94 | F19: =SUM(B19:D19) -> 2099.94
A20: MMO | B20: 3691.1 | F20: =SUM(B20:D20) -> 3691.1
A21: MNA | B21: 8894.2 | F21: =SUM(B21:D21) -> 8894.2
A22: MRO | C22: 106.33 | F22: =SUM(B22:D22) -> 106.33
A23: NSA | C23: 290 | F23: =SUM(B23:D23) -> 290
A24: NVB | B24: 789.5 | F24: =SUM(B24:D24) -> 789.5
A25: OHI | B25: 1392 | F25: =SUM(B25:D25) -> 1392
A26: OLA | B26: 650 | F26: =SUM(B26:D26) -> 650
A27: PLT | B27: 881.6 | C27: 870 | F27: =SUM(B27:D27) -> 1751.6
A28: SAD | B28: 756 | C28: 193.33 | E28: -67.2 | F28: =SUM(B28:E28) -> 882.13
A29: SAT | B29: 794.05 | F29: =SUM(B29:D29) -> 794.05
A30: SEJ | B30: 2509.45 | F30: =SUM(B30:D30) -> 2509.45
A31: SNA | B31: 672 | C31: 367.33 | F31: =SUM(B31:D31) -> 1039.33
A32: SSA | B32: 156 | F32: =SUM(B32:D32) -> 156
A33: VRI | B33: 2034.85 | F33: =SUM(B33:D33) -> 2034.85
A34: YMA | B34: 1008 | F34: =SUM(B34:D34) -> 1008
A35: Total général | B35: =SUM(B4:B34) -> 145548.11 | C35: =SUM(C4:C34) -> 11774.93 | D35: =SUM(D4:D34) -> 0 | F35: =SUM(F4:F34) -> 157255.84
A38: Annee | B38: Mois | C38: Projet | D38: Matricule_Consultant_Place | E38: Matricule_Percoit_Prime | F38: Type_Prime | G38: Nb_Jour | H38: Montant_Journalier_Cout_LL | I38: Montant_Mensuel_Cout_LL
A39: 2026 | B39: 6 | C39: AEA - PPO Moveo - VW IS | D39: AEA | E39: ADO | F39: Encadrement | I39: 290
A40: 2026 | B40: 4 | C40: MFE - Delivery Manager - VW IS | D40: MFE | E40: ADO | F40: Encadrement | I40: 290
A41: 2026 | B41: 5 | C41: MFE - Delivery Manager - VW IS | D41: MFE | E41: ADO | F41: Encadrement | I41: 290
A42: 2026 | B42: 6 | C42: MFE - Delivery Manager - VW IS | D42: MFE | E42: ADO | F42: Encadrement | I42: 290
A43: 2026 | B43: 4 | C43: AKE - BA Run editique - VW IS | D43: AKE | E43: ADO | F43: Encadrement | I43: 290
...

Sheet Prime Freelance T3 2026
A1: Montant des primes freelance pour le T3 2026
A3: Matricule_Perçoit_Prime | B3: Prime commerciale freelance | C3: Prime encadrement | D3: Correction prime | E3: Total général
A4: ACO | E4: =SUM(B4:D4) -> 0
A5: AMA | E5: =SUM(B5:D5) -> 0
A6: AMO | E6: =SUM(B6:D6) -> 0
A7: DMA | E7: =SUM(B7:D7) -> 0
A8: DZE | E8: =SUM(B8:D8) -> 0
A9: ELB | E9: =SUM(B9:D9) -> 0
A10: FGU | E10: =SUM(B10:D10) -> 0
A11: GBO | E11: =SUM(B11:D11) -> 0
A12: HZO | E12: =SUM(B12:D12) -> 0
A13: IAB | E13: =SUM(B13:D13) -> 0
A14: JBO | E14: =SUM(B14:D14) -> 0
A15: JHU | E15: =SUM(B15:D15) -> 0
... A32: VRI | E32: =SUM(B32:D32) -> 0
A33: Total général | B33: =sum(B4:B32) -> 0 | C33: =sum(C4:C32) -> 0 | D33: =sum(D4:D32) -> 0 | E33: =sum(E4:E32) -> 0
A36: Annee | B36: Mois | C36: Projet | D36: Matricule_Consultant_Place | E36: Matricule_Percoit_Prime | F36: Type_Prime | G36: Nb_Jour | H36: Montant_Journalier_Cout_LL | I36: Montant_Mensuel_Cout_LL

Sheet Prime Freelance T4 2026
A1: Montant des primes freelance pour le T4 2026
A3: Matricule_Perçoit_Prime | B3: Prime commerciale freelance | C3: Prime encadrement | D3: Total général
A4: AMA | D4: =SUM(B4:C4) -> 0
A5: AMO | D5: =SUM(B5:C5) -> 0
A6: DMA | D6: =SUM(B6:C6) -> 0
A7: DZE | D7: =SUM(B7:C7) -> 0
A8: ELB | D8: =SUM(B8:C8) -> 0
A9: FGU | D9: =SUM(B9:C9) -> 0
A10: GBO | D10: =SUM(B10:C10) -> 0
A11: GME | D11: =SUM(B11:C11) -> 0
A12: HZO | D12: =SUM(B12:C12) -> 0
A13: IAB | D13: =SUM(B13:C13) -> 0
A14: JBO | D14: =SUM(B14:C14) -> 0
A15: JHU | D15: =SUM(B15:C15) -> 0
... A30: VRI | D30: =SUM(B30:C30) -> 0
A31: Total général | B31: =sum(B4:B30) -> 0 | C31: =sum(C4:C30) -> 0 | D31: =SUM(D4:D30) -> 0
A34: Annee | B34: Mois | C34: Projet | D34: Matricule_Consultant_Place | E34: Matricule_Percoit_Prime | F34: Type_Prime | G34: Nb_Jour | H34: Montant_Journalier_Cout_LL | I34: Montant_Mensuel_Cout_LL
A35: 2025 | B35: 10 | C35: ABB - Pilote POA - SUEZ | D35: ABB | E35: JBO | F35: Commerciale freelance | G35: 17.5 | H35: 12.5 | I35: 218.75
A36: 2025 | B36: 11 | C36: ABB - Pilote POA - SUEZ | D36: ABB | E36: JBO | F36: Commerciale freelance | G36: 16.5 | H36: 12.5 | I36: 206.25
A37: 2025 | B37: 12 | C37: ABB - Pilote POA - SUEZ | D37: ABB | E37: JBO | F37: Commerciale freelance | G37: 18 | H37: 12.5 | I37: 225
A38: 2025 | B38: 10 | C38: ABO - Project Manager / Director-Advanced ENGIE | D38: ABO | E38: JBO | F38: Commerciale freelance | G38: 22 | H38: 10 | I38: 220
A39: 2025 | B39: 11 | C39: ABO - Project Manager / Director-Advanced ENGIE | D39: ABO | E39: JBO | F39: Commerciale freelance | G39: 17 | H39: 10 | I39: 170
A40: 2025 | B40: 12 | C40: ABO - Project Manager / Director-Advanced ENGIE | D40: ABO | E40: JBO | F40: Commerciale freelance | G40: 18 | H40: 10 | I40: 180
A41: 2025 | B41: 10 | C41: ACO - IT Product Manager pour MPS - TOTAL | D41: ACO | E41: AMA | F41: Commerciale freelance | G41: 0.5 | H41: 26.9 | I41: 13.45
A42: 2025 | B42: 11 | C42: Dispositif PO - TotalEnergies | D42: ABT | E42: MNA | F42: Commerciale freelance | G42: 4 | H42: 7.7 | I42: 30.8
A43: 2025 | B43: 10 | C43: ACO - IT Product Manager pour MPS - TOTAL | D43: ACO | E43: AMA | F43: Commerciale freelance | G43: 21.5 | H43: 26.9 | I43: 578.35
A44: 2025 | B44: 12 | C44: Dispositif PO - TotalEnergies | D44: ABT | E44: MNA | F44: Commerciale freelance | G44: 15 | H44: 7.7 | I44: 115.5
A45: 2025 | B45: 11 | C45: ACO - IT Product Manager pour MPS - TOTAL | D45: ACO | E45: AMA | F45: Commerciale freelance | G45: 18.5 | H45: 26.9 | I45: 497.65
A46: 2025 | B46: 12 | C46: ACO - IT Product Manager pour MPS - TOTAL | D46: ACO | E46: AMA | F46: Commerciale freelance | G46: 17.5 | H46: 26.9 | I46: 470.75
... A482: 2025 | B482: 12 | C482: VRI - JMT - GLA - Execution of Hubgrade@Scale - VNA | D482: GLA | E482: VRI | F482: Commerciale freelance | G482: 10 | H482: 26.9 | I482: 269
A483: 2025 | B483: 12 | C483: VRI - JMT - GLA - Execution of Hubgrade@Scale - VNA | D483: JMT | E483: VRI | F483: Commerciale freelance | G483: 6 | H483: 26.9 | I483: =G483*H483 -> 161.4
A484: 2025 | B484: 10 | C484: YLE - renfort RTE sur Agilisation Cardpro - TOTAL | D484: YLE | E484: GBO | F484: Commerciale freelance | G484: 9.5 | H484: 37.5 | I484: 356.25
A485: 2025 | B485: 10 | C485: YLE - renfort RTE sur Agilisation Cardpro - TOTAL | D485: YLE | E485: GBO | F485: Commerciale freelance | G485: 13 | H485: 37.5 | I485: 487.5
A486: 2025 | B486: 11 | C486: YLE - renfort RTE sur Agilisation Cardpro - TOTAL | D486: YLE | E486: GBO | F486: Commerciale freelance | G486: 18 | H486: 37.5 | I486: 675
A487: 2025 | B487: 12 | C487: YLE - renfort RTE sur Agilisation Cardpro - TOTAL | D487: YLE | E487: GBO | F487: Commerciale freelance | G487: 21 | H487: 37.5 | I487: 787.5
A488: 2025 | B488: 10 | C488: YLT - CP AMOA projet ITC - Franciliane | D488: YLT | E488: JBO | F488: Commerciale freelance | G488: 18.5 | H488: 7.5 | I488: 138.75
A489: 2025 | B489: 11 | C489: YLT - CP AMOA projet ITC - Franciliane | D489: YLT | E489: JBO | F489: Commerciale freelance | G489: 17 | H489: 7.5 | I489: 127.5
A490: 2025 | B490: 12 | C490: YLT - CP AMOA projet ITC - Franciliane | D490: YLT | E490: JBO | F490: Commerciale freelance | G490: 14 | H490: 7.5 | I490: 105
A491: 2025 | B491: 10 | C491: YRN - AMAO GMAO SPOT - SNCF | D491: YRN | E491: HZO | F491: Commerciale freelance | G491: 20 | H491: 13.1 | I491: 262
A492: 2025 | B492: 10 | C492: YRN - AMAO GMAO SPOT - SNCF | D492: YRN | E492: JBO | F492: Commerciale freelance | G492: 20 | H492: 5 | I492: 100
...

Sheet Prime "Qualité de la prestation
A1: Forfait calculé :
A2: 70€ pour 3 encadrements actifs à la fin de la période
A3: - 19 consultants en encadrement actif sans date de fin
A4: - 5 consultants dont l'encadrement s'est terminé sur le T1 2026
A6: T1 2026 | B6: Nbre | C6: Tarif
A7: Kick-off encadrement | B7: 9 | C7: 200 | D7: =B7*C7 -> 1800
A8: Suivi des encadrement | B8: 23 | C8: 23.33 | D8: =B8*C8 -> 536.59
D9: =SUM(D7:D8) -> 2336.59
A11: ATTENTION, Alex a surfacturé 1 suivi des encadrements sur le T1, a rattrapper sur le T2

Sheet Recap Salariés 2026
A1: Recap 2026 | M1: Valeur Action LL | N1: 55.39 | O1: Coef Brut Salarié --> AGA | P1: 1.15
A3: Prime perçue
A4: Matricule_Perçoit_Prime | B4: T1 | D4: T2 | F4: T3 | H4: T4 | J4: 2026 | N4: Conversion en Actions Gratuites 2023
B5: Prime | C5: Actions LL | D5: Prime | E5: Actions LL | F5: Prime | G5: Actions LL | H5: Prime | I5: Actions LL | J5: Total | K5: Prime | L5: Actions LL | M5: RATIO actions LL/Total | N5: Nb actions correspondantes | O5: Prime sur salaire € | Q5: Verif Montant action LL
A6: ADO | B6: =IF(ISNA(VLOOKUP($A6,'Prime Salariés T1 2026'!$A$3:$H$32,6,FALSE)),0,VLOOKUP($A6,'Prime Salariés T1 2026'!$A$3:$H$32,6,FALSE)) | C6: =IF(ISNA(VLOOKUP($A6,'Prime Salariés T1 2026'!$A$3:$H$32,7,FALSE)),0,VLOOKUP($A6,'Prime Salariés T1 2026'!$A$3:$H$32,7,FALSE)) | J6: =K6+L6 -> 0 | K6: =B6+D6+F6+H6 -> 0 | L6: =C6+E6+G6+I6 -> 0 | M6: =L6/J6 -> #DIV/0! | N6: =IF(L6<500,0,IF(L6<10000,INT(L6*$P$1/($N$1*0.7)),"formule a compléter")) -> 0 | O6: =L6-N6*(N$1*0.7)/P$1 -> 0 | Q6: =O6+N6*$N$1/$P$1 -> 0
A7: ANO | B7: =IF(ISNA(VLOOKUP($A7,'Prime Salariés T1 2026'!$A$3:$H$32,6,FALSE)),0,VLOOKUP($A7,'Prime Salariés T1 2026'!$A$3:$H$32,6,FALSE)) -> 104 | C7: =IF(ISNA(VLOOKUP($A7,'Prime Salariés T1 2026'!$A$3:$H$32,7,FALSE)),0,VLOOKUP($A7,'Prime Salariés T1 2026'!$A$3:$H$32,7,FALSE)) | D7: =IF(ISNA(VLOOKUP($A7,'Prime Salariés T2 2026'!$A$3:$G$22,6,FALSE)),0,VLOOKUP($A7,'Prime Salariés T2 2026'!$A$3:$G$22,6,FALSE)) -> 0 | E7: =IF(ISNA(VLOOKUP($A7,'Prime Salariés T2 2026'!$A$3:$G$22,7,FALSE)),0,VLOOKUP($A7,'Prime Salariés T2 2026'!$A$3:$G$22,7,FALSE)) -> 0 | F7: =IF(ISNA(VLOOKUP($A7,'Prime Salariés T3 2026'!$A$4:$I$26,6,FALSE)),0,VLOOKUP($A7,'Prime Salariés T3 2026'!$A$4:$I$26,6,FALSE)) | G7: =IF(ISNA(VLOOKUP($A7,'Prime Salariés T3 2026'!$A$4:$I$26,7,FALSE)),0,VLOOKUP($A7,'Prime Salariés T3 2026'!$A$4:$I$26,7,FALSE)) | H7: =IF(ISNA(VLOOKUP($A7,'Prime Salariés T4 2026'!$A$4:$H$28,5,FALSE)),0,VLOOKUP($A7,'Prime Salariés T4 2026'!$A$4:$H$28,5,FALSE)) -> 0 | I7: =IF(ISNA(VLOOKUP($A7,'Prime Salariés T4 2026'!$A$4:$H$28,7,FALSE)),0,VLOOKUP($A7,'Prime Salariés T4 2026'!$A$4:$H$28,7,FALSE)) | J7: =K7+L7 -> 104 | K7: =B7+D7+F7+H7 -> 104 | L7: =C7+E7+G7+I7 -> 0 | M7: =L7/J7 -> 0 | N7: =IF(L7<500,0,IF(L7<10000,INT(L7*$P$1/($N$1*0.7)),"formule a compléter")) -> 0 | O7: =L7-N7*(N$1*0.7)/P$1 -> 0 | Q7: =O7+N7*$N$1/$P$1 -> 0
A8: ARA | B8: =IF(ISNA(VLOOKUP($A8,'Prime Salariés T1 2026'!$A$3:$H$32,6,FALSE)),0,VLOOKUP($A8,'Prime Salariés T1 2026'!$A$3:$H$32,6,FALSE)) -> 1047 | C8: =IF(ISNA(VLOOKUP($A8,'Prime Salariés T1 2026'!$A$3:$H$32,7,FALSE)),0,VLOOKUP($A8,'Prime Salariés T1 2026'!$A$3:$H$32,7,FALSE)) | D8: =IF(ISNA(VLOOKUP($A8,'Prime Salariés T2 2026'!$A$3:$G$22,6,FALSE)),0,VLOOKUP($A8,'Prime Salariés T2 2026'!$A$3:$G$22,6,FALSE)) -> 1028 | E8: =IF(ISNA(VLOOKUP($A8,'Prime Salariés T2 2026'!$A$3:$G$22,7,FALSE)),0,VLOOKUP($A8,'Prime Salariés T2 2026'!$A$3:$G$22,7,FALSE)) | F8: =IF(ISNA(VLOOKUP($A8,'Prime Salariés T3 2026'!$A$4:$I$26,6,FALSE)),0,VLOOKUP($A8,'Prime Salariés T3 2026'!$A$4:$I$26,6,FALSE)) | G8: =IF(ISNA(VLOOKUP($A8,'Prime Salariés T3 2026'!$A$4:$I$26,7,FALSE)),0,VLOOKUP($A8,'Prime Salariés T3 2026'!$A$4:$I$26,7,FALSE)) | H8: =IF(ISNA(VLOOKUP($A8,'Prime Salariés T4 2026'!$A$4:$H$28,6,FALSE)),0,VLOOKUP($A8,'Prime Salariés T4 2026'!$A$4:$H$28,6,FALSE)) | I8: =IF(ISNA(VLOOKUP($A8,'Prime Salariés T4 2026'!$A$4:$H$28,7,FALSE)),0,VLOOKUP($A8,'Prime Salariés T4 2026'!$A$4:$H$28,7,FALSE)) | J8: =K8+L8 -> 2075 | K8: =B8+D8+F8+H8 -> 2075 | L8: =C8+E8+G8+I8 -> 0 | M8: =L8/J8 -> 0 | N8: =IF(L8<500,0,IF(L8<10000,INT(L8*$P$1/($N$1*0.7)),"formule a compléter")) -> 0 | O8: =L8-N8*(N$1*0.7)/P$1 -> 0 | Q8: =O8+N8*$N$1/$P$1 -> 0
A9: AVA | B9: =IF(ISNA(VLOOKUP($A9,'Prime Salariés T1 2026'!$A$3:$H$32,6,FALSE)),0,VLOOKUP($A9,'Prime Salariés T1 2026'!$A$3:$H$32,6,FALSE)) | C9: =IF(ISNA(VLOOKUP($A9,'Prime Salariés T1 2026'!$A$3:$H$32,7,FALSE)),0,VLOOKUP($A9,'Prime Salariés T1 2026'!$A$3:$H$32,7,FALSE)) -> 5101.23 | D9: =IF(ISNA(VLOOKUP($A9,'Prime Salariés T2 2026'!$A$3:$G$22,6,FALSE)),0,VLOOKUP($A9,'Prime Salariés T2 2026'!$A$3:$G$22,6,FALSE)) | E9: =IF(ISNA(VLOOKUP($A9,'Prime Salariés T2 2026'!$A$3:$G$22,7,FALSE)),0,VLOOKUP($A9,'Prime Salariés T2 2026'!$A$3:$G$22,7,FALSE)) -> 3797 | F9: =IF(ISNA(VLOOKUP($A9,'Prime Salariés T3 2026'!$A$4:$I$26,6,FALSE)),0,VLOOKUP($A9,'Prime Salariés T3 2026'!$A$4:$I$26,6,FALSE)) | G9: =IF(ISNA(VLOOKUP($A9,'Prime Salariés T3 2026'!$A$4:$I$26,7,FALSE)),0,VLOOKUP($A9,'Prime Salariés T3 2026'!$A$4:$I$26,7,FALSE)) | H9: =IF(ISNA(VLOOKUP($A9,'Prime Salariés T4 2026'!$A$4:$H$28,6,FALSE)),0,VLOOKUP($A9,'Prime Salariés T4 2026'!$A$4:$H$28,6,FALSE)) | I9: =IF(ISNA(VLOOKUP($A9,'Prime Salariés T4 2026'!$A$4:$H$28,7,FALSE)),0,VLOOKUP($A9,'Prime Salariés T4 2026'!$A$4:$H$28,7,FALSE)) | J9: =K9+L9 -> 8898.23 | K9: =B9+D9+F9+H9 -> 0 | L9: =C9+E9+G9+I9 -> 8898.23
A10: CLM | J10: =K10+L10 -> 0 | K10: =B10+D10+F10+H10 -> 0 | L10: =C10+E10+G10+I10 -> 0 | M10: =L10/J10 -> #DIV/0! | N10: =IF(L10<500,0,IF(L10<10000,INT(L10*$P$1/($N$1*0.7)),"formule a compléter")) -> 0 | O10: =L10-N10*(N$1*0.7)/P$1 -> 0 | Q10: =O10+N10*$N$1/$P$1 -> 0
A11: CME | B11: =IF(ISNA(VLOOKUP($A11,'Prime Salariés T1 2026'!$A$3:$H$32,6,FALSE)),0,VLOOKUP($A11,'Prime Salariés T1 2026'!$A$3:$H$32,6,FALSE)) | C11: =IF(ISNA(VLOOKUP($A11,'Prime Salariés T1 2026'!$A$3:$H$32,7,FALSE)),0,VLOOKUP($A11,'Prime Salariés T1 2026'!$A$3:$H$32,7,FALSE)) -> 2920 | D11: =IF(ISNA(VLOOKUP($A11,'Prime Salariés T2 2026'!$A$3:$G$22,6,FALSE)),0,VLOOKUP($A11,'Prime Salariés T2 2026'!$A$3:$G$22,6,FALSE)) | E11: =IF(ISNA(VLOOKUP($A11,'Prime Salariés T2 2026'!$A$3:$G$22,7,FALSE)),0,VLOOKUP($A11,'Prime Salariés T2 2026'!$A$3:$G$22,7,FALSE)) -> 2125 | F11: =IF(ISNA(VLOOKUP($A11,'Prime Salariés T3 2026'!$A$4:$I$26,6,FALSE)),0,VLOOKUP($A11,'Prime Salariés T3 2026'!$A$4:$I$26,6,FALSE)) | G11: =IF(ISNA(VLOOKUP($A11,'Prime Salariés T3 2026'!$A$4:$I$26,7,FALSE)),0,VLOOKUP($A11,'Prime Salariés T3 2026'!$A$4:$I$26,7,FALSE)) | H11: =IF(ISNA(VLOOKUP($A11,'Prime Salariés T4 2026'!$A$4:$H$28,6,FALSE)),0,VLOOKUP($A11,'Prime Salariés T4 2026'!$A$4:$H$28,6,FALSE)) | I11: =IF(ISNA(VLOOKUP($A11,'Prime Salariés T4 2026'!$A$4:$H$28,7,FALSE)),0,VLOOKUP($A11,'Prime Salariés T4 2026'!$A$4:$H$28,7,FALSE)) | J11: =K11+L11 -> 5045 | K11: =B11+D11+F11+H11 -> 0 | L11: =C11+E11+G11+I11 -> 5045 | N11: =IF(L11<500,0,IF(L11<10000,INT(L11*$P$1/($N$1*0.7)),"formule a compléter")) -> 149 | O11: =L11-N11*(N$1*0.7)/P$1 -> 21.367826 | Q11: =O11+N11*$N$1/$P$1 -> 7197.9852
A12: GBE | B12: =IF(ISNA(VLOOKUP($A12,'Prime Salariés T1 2026'!$A$3:$H$32,6,FALSE)),0,VLOOKUP($A12,'Prime Salariés T1 2026'!$A$3:$H$32,6,FALSE)) | C12: =IF(ISNA(VLOOKUP($A12,'Prime Salariés T1 2026'!$A$3:$H$32,7,FALSE)),0,VLOOKUP($A12,'Prime Salariés T1 2026'!$A$3:$H$32,7,FALSE)) -> 1010 | D12: =IF(ISNA(VLOOKUP($A12,'Prime Salariés T2 2026'!$A$3:$G$22,6,FALSE)),0,VLOOKUP($A12,'Prime Salariés T2 2026'!$A$3:$G$22,6,FALSE)) | E12: =IF(ISNA(VLOOKUP($A12,'Prime Salariés T2 2026'!$A$3:$G$22,7,FALSE)),0,VLOOKUP($A12,'Prime Salariés T2 2026'!$A$3:$G$22,7,FALSE)) -> 1355 | F12: =IF(ISNA(VLOOKUP($A12,'Prime Salariés T3 2026'!$A$4:$I$26,6,FALSE)),0,VLOOKUP($A12,'Prime Salariés T3 2026'!$A$4:$I$26,6,FALSE)) | G12: =IF(ISNA(VLOOKUP($A12,'Prime Salariés T3 2026'!$A$4:$I$26,7,FALSE)),0,VLOOKUP($A12,'Prime Salariés T3 2026'!$A$4:$I$26,7,FALSE)) | H12: =IF(ISNA(VLOOKUP($A12,'Prime Salariés T4 2026'!$A$4:$H$28,6,FALSE)),0,VLOOKUP($A12,'Prime Salariés T4 2026'!$A$4:$H$28,6,FALSE)) | I12: =IF(ISNA(VLOOKUP($A12,'Prime Salariés T4 2026'!$A$4:$H$28,7,FALSE)),0,VLOOKUP($A12,'Prime Salariés T4 2026'!$A$4:$H$28,7,FALSE)) | J12: =K12+L12 -> 2365 | K12: =B12+D12+F12+H12 -> 0 | L12: =C12+E12+G12+I12 -> 2365
A13: GSA | B13: =IF(ISNA(VLOOKUP($A13,'Prime Salariés T1 2026'!$A$3:$H$32,6,FALSE)),0,VLOOKUP($A13,'Prime Salariés T1 2026'!$A$3:$H$32,6,FALSE)) | C13: =IF(ISNA(VLOOKUP($A13,'Prime Salariés T1 2026'!$A$3:$H$32,7,FALSE)),0,VLOOKUP($A13,'Prime Salariés T1 2026'!$A$3:$H$32,7,FALSE)) -> 471 | D13: =IF(ISNA(VLOOKUP($A13,'Prime Salariés T2 2026'!$A$3:$G$22,6,FALSE)),0,VLOOKUP($A13,'Prime Salariés T2 2026'!$A$3:$G$22,6,FALSE)) | E13: =IF(ISNA(VLOOKUP($A13,'Prime Salariés T2 2026'!$A$3:$G$22,7,FALSE)),0,VLOOKUP($A13,'Prime Salariés T2 2026'!$A$3:$G$22,7,FALSE)) -> 324 | F13: =IF(ISNA(VLOOKUP($A13,'Prime Salariés T3 2026'!$A$4:$I$26,6,FALSE)),0,VLOOKUP($A13,'Prime Salariés T3 2026'!$A$4:$I$26,6,FALSE)) | G13: =IF(ISNA(VLOOKUP($A13,'Prime Salariés T3 2026'!$A$4:$I$26,7,FALSE)),0,VLOOKUP($A13,'Prime Salariés T3 2026'!$A$4:$I$26,7,FALSE)) | H13: =IF(ISNA(VLOOKUP($A13,'Prime Salariés T4 2026'!$A$4:$H$28,6,FALSE)),0,VLOOKUP($A13,'Prime Salariés T4 2026'!$A$4:$H$28,6,FALSE)) | I13: =IF(ISNA(VLOOKUP($A13,'Prime Salariés T4 2026'!$A$4:$H$28,7,FALSE)),0,VLOOKUP($A13,'Prime Salariés T4 2026'!$A$4:$H$28,7,FALSE)) | J13: =K13+L13 -> 795 | K13: =B13+D13+F13+H13 -> 0 | L13: =C13+E13+G13+I13 -> 795 | M13: =L13/J13 -> 1 | N13: =IF(L13<500,0,IF(L13<10000,INT(L13*$P$1/($N$1*0.7)),"formule a compléter")) -> 23 | O13: =L13-N13*(N$1*0.7)/P$1 -> 19.54 | Q13: =O13+N13*$N$1/$P$1 -> 1127.34
A14: GTA | B14: =IF(ISNA(VLOOKUP($A14,'Prime Salariés T1 2026'!$A$3:$H$32,6,FALSE)),0,VLOOKUP($A14,'Prime Salariés T1 2026'!$A$3:$H$32,6,FALSE)) -> 1234 | C14: =IF(ISNA(VLOOKUP($A14,'Prime Salariés T1 2026'!$A$3:$H$32,7,FALSE)),0,VLOOKUP($A14,'Prime Salariés T1 2026'!$A$3:$H$32,7,FALSE)) | D14: =IF(ISNA(VLOOKUP($A14,'Prime Salariés T2 2026'!$A$3:$G$22,6,FALSE)),0,VLOOKUP($A14,'Prime Salariés T2 2026'!$A$3:$G$22,6,FALSE)) -> 997 | E14: =IF(ISNA(VLOOKUP($A14,'Prime Salariés T2 2026'!$A$3:$G$22,7,FALSE)),0,VLOOKUP($A14,'Prime Salariés T2 2026'!$A$3:$G$22,7,FALSE)) | F14: =IF(ISNA(VLOOKUP($A14,'Prime Salariés T3 2026'!$A$4:$I$26,6,FALSE)),0,VLOOKUP($A14,'Prime Salariés T3 2026'!$A$4:$I$26,6,FALSE)) | G14: =IF(ISNA(VLOOKUP($A14,'Prime Salariés T3 2026'!$A$4:$I$26,7,FALSE)),0,VLOOKUP($A14,'Prime Salariés T3 2026'!$A$4:$I$26,7,FALSE)) | H14: =IF(ISNA(VLOOKUP($A14,'Prime Salariés T4 2026'!$A$4:$H$28,6,FALSE)),0,VLOOKUP($A14,'Prime Salariés T4 2026'!$A$4:$H$28,6,FALSE)) | I14: =IF(ISNA(VLOOKUP($A14,'Prime Salariés T4 2026'!$A$4:$H$28,7,FALSE)),0,VLOOKUP($A14,'Prime Salariés T4 2026'!$A$4:$H$28,7,FALSE)) | J14: =K14+L14 -> 2231 | K14: =B14+D14+F14+H14 -> 2231 | L14: =C14+E14+G14+I14 -> 0 | M14: =L14/J14 -> 0 | N14: =IF(L14<500,0,IF(L14<10000,INT(L14*$P$1/($N$1*0.7)),"formule a compléter")) -> 0 | O14: =L14-N14*(N$1*0.7)/P$1 -> 0 | Q14: =O14+N14*$N$1/$P$1 -> 0
A15: IHA | B15: =IF(ISNA(VLOOKUP($A15,'Prime Salariés T1 2026'!$A$3:$H$32,6,FALSE)),0,VLOOKUP($A15,'Prime Salariés T1 2026'!$A$3:$H$32,6,FALSE)) -> 794 | C15: =IF(ISNA(VLOOKUP($A15,'Prime Salariés T1 2026'!$A$3:$H$32,7,FALSE)),0,VLOOKUP($A15,'Prime Salariés T1 2026'!$A$3:$H$32,7,FALSE)) | D15: =IF(ISNA(VLOOKUP($A15,'Prime Salariés T2 2026'!$A$3:$G$22,6,FALSE)),0,VLOOKUP($A15,'Prime Salariés T2 2026'!$A$3:$G$22,6,FALSE)) -> 811 | E15: =IF(ISNA(VLOOKUP($A15,'Prime Salariés T2 2026'!$A$3:$G$22,7,FALSE)),0,VLOOKUP($A15,'Prime Salariés T2 2026'!$A$3:$G$22,7,FALSE)) | F15: =IF(ISNA(VLOOKUP($A15,'Prime Salariés T3 2026'!$A$4:$I$26,6,FALSE)),0,VLOOKUP($A15,'Prime Salariés T3 2026'!$A$4:$I$26,6,FALSE)) | G15: =IF(ISNA(VLOOKUP($A15,'Prime Salariés T3 2026'!$A$4:$I$26,7,FALSE)),0,VLOOKUP($A15,'Prime Salariés T3 2026'!$A$4:$I$26,7,FALSE)) | H15: =IF(ISNA(VLOOKUP($A15,'Prime Salariés T4 2026'!$A$4:$H$28,6,FALSE)),0,VLOOKUP($A15,'Prime Salariés T4 2026'!$A$4:$H$28,6,FALSE)) | I15: =IF(ISNA(VLOOKUP($A15,'Prime Salariés T4 2026'!$A$4:$H$28,7,FALSE)),0,VLOOKUP($A15,'Prime Salariés T4 2026'!$A$4:$H$28,7,FALSE)) | J15: =K15+L15 -> 1605 | K15: =B15+D15+F15+H15 -> 1605 | L15: =C15+E15+G15+I15 -> 0
A16: JDU | B16: =IF(ISNA(VLOOKUP($A16,'Prime Salariés T1 2026'!$A$3:$H$32,6,FALSE)),0,VLOOKUP($A16,'Prime Salariés T1 2026'!$A$3:$H$32,6,FALSE)) -> 975 | C16: =IF(ISNA(VLOOKUP($A16,'Prime Salariés T1 2026'!$A$3:$H$32,7,FALSE)),0,VLOOKUP($A16,'Prime Salariés T1 2026'!$A$3:$H$32,7,FALSE)) | D16: =IF(ISNA(VLOOKUP($A16,'Prime Salariés T2 2026'!$A$3:$G$22,6,FALSE)),0,VLOOKUP($A16,'Prime Salariés T2 2026'!$A$3:$G$22,6,FALSE)) -> 1272 | E16: =IF(ISNA(VLOOKUP($A16,'Prime Salariés T2 2026'!$A$3:$G$22,7,FALSE)),0,VLOOKUP($A16,'Prime Salariés T2 2026'!$A$3:$G$22,7,FALSE)) | F16: =IF(ISNA(VLOOKUP($A16,'Prime Salariés T3 2026'!$A$4:$I$26,6,FALSE)),0,VLOOKUP($A16,'Prime Salariés T3 2026'!$A$4:$I$26,6,FALSE)) -> 0 | G16: =IF(ISNA(VLOOKUP($A16,'Prime Salariés T3 2026'!$A$4:$I$26,7,FALSE)),0,VLOOKUP($A16,'Prime Salariés T3 2026'!$A$4:$I$26,7,FALSE)) -> 0 | H16: =IF(ISNA(VLOOKUP($A16,'Prime Salariés T4 2026'!$A$4:$H$28,6,FALSE)),0,VLOOKUP($A16,'Prime Salariés T4 2026'!$A$4:$H$28,6,FALSE)) | I16: =IF(ISNA(VLOOKUP($A16,'Prime Salariés T4 2026'!$A$4:$H$28,7,FALSE)),0,VLOOKUP($A16,'Prime Salariés T4 2026'!$A$4:$H$28,7,FALSE)) | J16: =K16+L16 -> 2247 | K16: =B16+D16+F16+H16 -> 2247 | L16: =C16+E16+G16+I16 -> 0 | M16: =L16/J16 -> 0 | N16: =IF(L16<500,0,IF(L16<10000,INT(L16*$P$1/($N$1*0.7)),"formule a compléter")) -> 0 | O16: =L16-N16*(N$1*0.7)/P$1 -> 0 | Q16: =O16+N16*$N$1/$P$1 -> 0
A17: JFE | B17: =IF(ISNA(VLOOKUP($A17,'Prime Salariés T1 2026'!$A$3:$H$32,6,FALSE)),0,VLOOKUP($A17,'Prime Salariés T1 2026'!$A$3:$H$32,6,FALSE)) -> 387 | C17: =IF(ISNA(VLOOKUP($A17,'Prime Salariés T1 2026'!$A$3:$H$32,7,FALSE)),0,VLOOKUP($A17,'Prime Salariés T1 2026'!$A$3:$H$32,7,FALSE)) | D17: =IF(ISNA(VLOOKUP($A17,'Prime Salariés T2 2026'!$A$3:$G$22,6,FALSE)),0,VLOOKUP($A17,'Prime Salariés T2 2026'!$A$3:$G$22,6,FALSE)) -> 441 | E17: =IF(ISNA(VLOOKUP($A17,'Prime Salariés T2 2026'!$A$3:$G$22,7,FALSE)),0,VLOOKUP($A17,'Prime Salariés T2 2026'!$A$3:$G$22,7,FALSE)) | F17: =IF(ISNA(VLOOKUP($A17,'Prime Salariés T3 2026'!$A$4:$I$26,6,FALSE)),0,VLOOKUP($A17,'Prime Salariés T3 2026'!$A$4:$I$26,6,FALSE)) | G17: =IF(ISNA(VLOOKUP($A17,'Prime Salariés T3 2026'!$A$4:$I$26,7,FALSE)),0,VLOOKUP($A17,'Prime Salariés T3 2026'!$A$4:$I$26,7,FALSE)) | H17: =IF(ISNA(VLOOKUP($A17,'Prime Salariés T4 2026'!$A$4:$H$28,6,FALSE)),0,VLOOKUP($A17,'Prime Salariés T4 2026'!$A$4:$H$28,6,FALSE)) | I17: =IF(ISNA(VLOOKUP($A17,'Prime Salariés T4 2026'!$A$4:$H$28,7,FALSE)),0,VLOOKUP($A17,'Prime Salariés T4 2026'!$A$4:$H$28,7,FALSE)) | J17: =K17+L17 -> 828 | K17: =B17+D17+F17+H17 -> 828 | L17: =C17+E17+G17+I17 -> 0 | N17: =IF(L17<500,0,IF(L17<10000,INT(L17*$P$1/($N$1*0.7)),"formule a compléter")) -> 0 | O17: =L17-N17*(N$1*0.7)/P$1 -> 0 | Q17: =O17+N17*$N$1/$P$1 -> 0
A18: KSA | D18: =IF(ISNA(VLOOKUP($A18,'Prime Salariés T2 2026'!$A$3:$G$22,6,FALSE)),0,VLOOKUP($A18,'Prime Salariés T2 2026'!$A$3:$G$22,6,FALSE)) | E18: =IF(ISNA(VLOOKUP($A18,'Prime Salariés T2 2026'!$A$3:$G$22,7,FALSE)),0,VLOOKUP($A18,'Prime Salariés T2 2026'!$A$3:$G$22,7,FALSE)) -> 500 | F18: =IF(ISNA(VLOOKUP($A18,'Prime Salariés T3 2026'!$A$4:$I$26,6,FALSE)),0,VLOOKUP($A18,'Prime Salariés T3 2026'!$A$4:$I$26,6,FALSE)) -> 0 | G18: =IF(ISNA(VLOOKUP($A18,'Prime Salariés T3 2026'!$A$4:$I$26,7,FALSE)),0,VLOOKUP($A18,'Prime Salariés T3 2026'!$A$4:$I$26,7,FALSE)) -> 0 | H18: =IF(ISNA(VLOOKUP($A18,'Prime Salariés T4 2026'!$A$4:$H$28,6,FALSE)),0,VLOOKUP($A18,'Prime Salariés T4 2026'!$A$4:$H$28,6,FALSE)) -> 0 | I18: =IF(ISNA(VLOOKUP($A18,'Prime Salariés T4 2026'!$A$4:$H$28,7,FALSE)),0,VLOOKUP($A18,'Prime Salariés T4 2026'!$A$4:$H$28,7,FALSE)) -> 0 | J18: =K18+L18 -> 500 | K18: =B18+D18+F18+H18 -> 0 | L18: =C18+E18+G18+I18 -> 500
A19: JGA | B19: =IF(ISNA(VLOOKUP($A19,'Prime Salariés T1 2026'!$A$3:$H$32,6,FALSE)),0,VLOOKUP($A19,'Prime Salariés T1 2026'!$A$3:$H$32,6,FALSE)) -> 600 | C19: =IF(ISNA(VLOOKUP($A19,'Prime Salariés T1 2026'!$A$3:$H$32,7,FALSE)),0,VLOOKUP($A19,'Prime Salariés T1 2026'!$A$3:$H$32,7,FALSE)) | D19: =IF(ISNA(VLOOKUP($A19,'Prime Salariés T2 2026'!$A$3:$G$22,6,FALSE)),0,VLOOKUP($A19,'Prime Salariés T2 2026'!$A$3:$G$22,6,FALSE)) -> 0 | E19: =IF(ISNA(VLOOKUP($A19,'Prime Salariés T2 2026'!$A$3:$G$22,7,FALSE)),0,VLOOKUP($A19,'Prime Salariés T2 2026'!$A$3:$G$22,7,FALSE)) -> 0 | F19: =IF(ISNA(VLOOKUP($A19,'Prime Salariés T3 2026'!$A$4:$I$26,6,FALSE)),0,VLOOKUP($A19,'Prime Salariés T3 2026'!$A$4:$I$26,6,FALSE)) -> 0 | G19: =IF(ISNA(VLOOKUP($A19,'Prime Salariés T3 2026'!$A$4:$I$26,7,FALSE)),0,VLOOKUP($A19,'Prime Salariés T3 2026'!$A$4:$I$26,7,FALSE)) -> 0 | H19: =IF(ISNA(VLOOKUP($A19,'Prime Salariés T4 2026'!$A$4:$H$28,6,FALSE)),0,VLOOKUP($A19,'Prime Salariés T4 2026'!$A$4:$H$28,6,FALSE)) | I19: =IF(ISNA(VLOOKUP($A19,'Prime Salariés T4 2026'!$A$4:$H$28,7,FALSE)),0,VLOOKUP($A19,'Prime Salariés T4 2026'!$A$4:$H$28,7,FALSE)) | J19: =K19+L19 -> 600 | K19: =B19+D19+F19+H19 -> 600 | L19: =C19+E19+G19+I19 -> 0
A20: LBU | B20: =IF(ISNA(VLOOKUP($A20,'Prime Salariés T1 2026'!$A$3:$H$32,6,FALSE)),0,VLOOKUP($A20,'Prime Salariés T1 2026'!$A$3:$H$32,6,FALSE)) -> 414 | C20: =IF(ISNA(VLOOKUP($A20,'Prime Salariés T1 2026'!$A$3:$H$32,7,FALSE)),0,VLOOKUP($A20,'Prime Salariés T1 2026'!$A$3:$H$32,7,FALSE)) | D20: =IF(ISNA(VLOOKUP($A20,'Prime Salariés T2 2026'!$A$3:$G$22,6,FALSE)),0,VLOOKUP($A20,'Prime Salariés T2 2026'!$A$3:$G$22,6,FALSE)) -> 349 | E20: =IF(ISNA(VLOOKUP($A20,'Prime Salariés T2 2026'!$A$3:$G$22,7,FALSE)),0,VLOOKUP($A20,'Prime Salariés T2 2026'!$A$3:$G$22,7,FALSE)) | F20: =IF(ISNA(VLOOKUP($A20,'Prime Salariés T3 2026'!$A$4:$I$26,6,FALSE)),0,VLOOKUP($A20,'Prime Salariés T3 2026'!$A$4:$I$26,6,FALSE)) -> 0 | G20: =IF(ISNA(VLOOKUP($A20,'Prime Salariés T3 2026'!$A$4:$I$26,7,FALSE)),0,VLOOKUP($A20,'Prime Salariés T3 2026'!$A$4:$I$26,7,FALSE)) -> 0 | H20: =IF(ISNA(VLOOKUP($A20,'Prime Salariés T4 2026'!$A$4:$H$28,6,FALSE)),0,VLOOKUP($A20,'Prime Salariés T4 2026'!$A$4:$H$28,6,FALSE)) -> 0 | I20: =IF(ISNA(VLOOKUP($A20,'Prime Salariés T4 2026'!$A$4:$H$28,7,FALSE)),0,VLOOKUP($A20,'Prime Salariés T4 2026'!$A$4:$H$28,7,FALSE)) -> 0 | J20: =K20+L20 -> 763 | K20: =B20+D20+F20+H20 -> 763 | L20: =C20+E20+G20+I20 -> 0 | M20: =L21/J21 -> #DIV/0! | N20: =IF(L21<500,0,IF(L21<10000,INT(L21*$P$1/($N$1*0.7)),"formule a compléter")) -> 0 | O20: =L21-N20*(N$1*0.7)/P$1 -> 0 | Q20: =O20+N20*$N$1/$P$1 -> 0
A21: LDO | J21: =K21+L21 -> 0 | K21: =B21+D21+F21+H21 -> 0 | L21: =C21+E21+G21+I21 -> 0
A22: MGU | B22: =IF(ISNA(VLOOKUP($A22,'Prime Salariés T1 2026'!$A$3:$H$32,6,FALSE)),0,VLOOKUP($A22,'Prime Salariés T1 2026'!$A$3:$H$32,6,FALSE)) | C22: =IF(ISNA(VLOOKUP($A22,'Prime Salariés T1 2026'!$A$3:$H$32,7,FALSE)),0,VLOOKUP($A22,'Prime Salariés T1 2026'!$A$3:$H$32,7,FALSE)) -> 764 | D22: =IF(ISNA(VLOOKUP($A22,'Prime Salariés T2 2026'!$A$3:$G$22,6,FALSE)),0,VLOOKUP($A22,'Prime Salariés T2 2026'!$A$3:$G$22,6,FALSE)) | E22: =IF(ISNA(VLOOKUP($A22,'Prime Salariés T2 2026'!$A$3:$G$22,7,FALSE)),0,VLOOKUP($A22,'Prime Salariés T2 2026'!$A$3:$G$22,7,FALSE)) -> 681 | F22: =IF(ISNA(VLOOKUP($A22,'Prime Salariés T3 2026'!$A$4:$I$26,6,FALSE)),0,VLOOKUP($A22,'Prime Salariés T3 2026'!$A$4:$I$26,6,FALSE)) | G22: =IF(ISNA(VLOOKUP($A22,'Prime Salariés T3 2026'!$A$4:$I$26,7,FALSE)),0,VLOOKUP($A22,'Prime Salariés T3 2026'!$A$4:$I$26,7,FALSE)) | H22: =IF(ISNA(VLOOKUP($A22,'Prime Salariés T4 2026'!$A$4:$H$28,6,FALSE)),0,VLOOKUP($A22,'Prime Salariés T4 2026'!$A$4:$H$28,6,FALSE)) | I22: =IF(ISNA(VLOOKUP($A22,'Prime Salariés T4 2026'!$A$4:$H$28,7,FALSE)),0,VLOOKUP($A22,'Prime Salariés T4 2026'!$A$4:$H$28,7,FALSE)) | J22: =K22+L22 -> 1445 | K22: =B22+D22+F22+H22 -> 0 | L22: =C22+E22+G22+I22 -> 1445 | M22: =L23/J23 -> 0 | N22: =IF(L23<500,0,IF(L23<10000,INT(L23*$P$1/($N$1*0.7)),"formule a compléter")) -> 0 | O22: =L23-N22*(N$1*0.7)/P$1 -> 0 | Q22: =O22+N22*$N$1/$P$1 -> 0
A23: MMA | B23: =IF(ISNA(VLOOKUP($A23,'Prime Salariés T1 2026'!$A$3:$H$32,6,FALSE)),0,VLOOKUP($A23,'Prime Salariés T1 2026'!$A$3:$H$32,6,FALSE)) -> 600 | C23: =IF(ISNA(VLOOKUP($A23,'Prime Salariés T1 2026'!$A$3:$H$32,7,FALSE)),0,VLOOKUP($A23,'Prime Salariés T1 2026'!$A$3:$H$32,7,FALSE)) | D23: =IF(ISNA(VLOOKUP($A23,'Prime Salariés T2 2026'!$A$3:$G$22,6,FALSE)),0,VLOOKUP($A23,'Prime Salariés T2 2026'!$A$3:$G$22,6,FALSE)) -> 400 | E23: =IF(ISNA(VLOOKUP($A23,'Prime Salariés T2 2026'!$A$3:$G$22,7,FALSE)),0,VLOOKUP($A23,'Prime Salariés T2 2026'!$A$3:$G$22,7,FALSE)) | F23: =IF(ISNA(VLOOKUP($A23,'Prime Salariés T3 2026'!$A$4:$I$26,6,FALSE)),0,VLOOKUP($A23,'Prime Salariés T3 2026'!$A$4:$I$26,6,FALSE)) -> 0 | G23: =IF(ISNA(VLOOKUP($A23,'Prime Salariés T3 2026'!$A$4:$I$26,7,FALSE)),0,VLOOKUP($A23,'Prime Salariés T3 2026'!$A$4:$I$26,7,FALSE)) -> 0 | H23: =IF(ISNA(VLOOKUP($A23,'Prime Salariés T4 2026'!$A$4:$H$28,6,FALSE)),0,VLOOKUP($A23,'Prime Salariés T4 2026'!$A$4:$H$28,6,FALSE)) | I23: =IF(ISNA(VLOOKUP($A23,'Prime Salariés T4 2026'!$A$4:$H$28,7,FALSE)),0,VLOOKUP($A23,'Prime Salariés T4 2026'!$A$4:$H$28,7,FALSE)) | J23: =K23+L23 -> 1000 | K23: =B23+D23+F23+H23 -> 1000 | L23: =C23+E23+G23+I23 -> 0 | M23: =IF(ISNA(VLOOKUP($A25,'Prime Salariés T1 2026'!$A$3:$H$32,6,FALSE)),0,VLOOKUP($A25,'Prime Salariés T1 2026'!$A$3:$H$32,6,FALSE)) -> 227 | N23: =IF(ISNA(VLOOKUP($A25,'Prime Salariés T1 2026'!$A$3:$H$32,7,FALSE)),0,VLOOKUP($A25,'Prime Salariés T1 2026'!$A$3:$H$32,7,FALSE)) | O23: =IF(ISNA(VLOOKUP($A25,'Prime Salariés T2 2026'!$A$3:$G$22,7,FALSE)),0,VLOOKUP($A25,'Prime Salariés T2 2026'!$A$3:$G$22,7,FALSE)) | P23: =IF(ISNA(VLOOKUP($A25,'Prime Salariés T2 2026'!$A$3:$G$22,8,FALSE)),0,VLOOKUP($A25,'Prime Salariés T2 2026'!$A$3:$G$22,8,FALSE)) -> #REF!
A24: MTO | B24: =IF(ISNA(VLOOKUP($A24,'Prime Salariés T1 2026'!$A$3:$H$32,6,FALSE)),0,VLOOKUP($A24,'Prime Salariés T1 2026'!$A$3:$H$32,6,FALSE)) -> 0 | C24: =IF(ISNA(VLOOKUP($A24,'Prime Salariés T1 2026'!$A$3:$H$32,7,FALSE)),0,VLOOKUP($A24,'Prime Salariés T1 2026'!$A$3:$H$32,7,FALSE)) -> 0 | D24: =IF(ISNA(VLOOKUP($A24,'Prime Salariés T2 2026'!$A$3:$G$22,6,FALSE)),0,VLOOKUP($A24,'Prime Salariés T2 2026'!$A$3:$G$22,6,FALSE)) -> 890.69 | E24: =IF(ISNA(VLOOKUP($A24,'Prime Salariés T2 2026'!$A$3:$G$22,7,FALSE)),0,VLOOKUP($A24,'Prime Salariés T2 2026'!$A$3:$G$22,7,FALSE)) | F24: =IF(ISNA(VLOOKUP($A24,'Prime Salariés T3 2026'!$A$4:$I$26,6,FALSE)),0,VLOOKUP($A24,'Prime Salariés T3 2026'!$A$4:$I$26,6,FALSE)) | G24: =IF(ISNA(VLOOKUP($A24,'Prime Salariés T3 2026'!$A$4:$I$26,7,FALSE)),0,VLOOKUP($A24,'Prime Salariés T3 2026'!$A$4:$I$26,7,FALSE)) | H24: =IF(ISNA(VLOOKUP($A24,'Prime Salariés T4 2026'!$A$4:$H$28,6,FALSE)),0,VLOOKUP($A24,'Prime Salariés T4 2026'!$A$4:$H$28,6,FALSE)) | I24: =IF(ISNA(VLOOKUP($A24,'Prime Salariés T4 2026'!$A$4:$H$28,7,FALSE)),0,VLOOKUP($A24,'Prime Salariés T4 2026'!$A$4:$H$28,7,FALSE)) | J24: =K24+L24 -> 890.69 | K24: =B24+D24+F24+H24 -> 890.69 | L24: =C24+E24+G24+I24 -> 0
A25: NOU | B25: =IF(ISNA(VLOOKUP($A25,'Prime Salariés T1 2026'!$A$3:$H$32,6,FALSE)),0,VLOOKUP($A25,'Prime Salariés T1 2026'!$A$3:$H$32,6,FALSE)) -> 227 | C25: =IF(ISNA(VLOOKUP($A25,'Prime Salariés T1 2026'!$A$3:$H$32,7,FALSE)),0,VLOOKUP($A25,'Prime Salariés T1 2026'!$A$3:$H$32,7,FALSE)) | D25: =IF(ISNA(VLOOKUP($A25,'Prime Salariés T2 2026'!$A$3:$G$22,6,FALSE)),0,VLOOKUP($A25,'Prime Salariés T2 2026'!$A$3:$G$22,6,FALSE)) -> 138 | E25: =IF(ISNA(VLOOKUP($A25,'Prime Salariés T2 2026'!$A$3:$G$22,7,FALSE)),0,VLOOKUP($A25,'Prime Salariés T2 2026'!$A$3:$G$22,7,FALSE)) | F25: =IF(ISNA(VLOOKUP($A25,'Prime Salariés T3 2026'!$A$4:$I$26,6,FALSE)),0,VLOOKUP($A25,'Prime Salariés T3 2026'!$A$4:$I$26,6,FALSE)) | G25: =IF(ISNA(VLOOKUP($A25,'Prime Salariés T3 2026'!$A$4:$I$26,7,FALSE)),0,VLOOKUP($A25,'Prime Salariés T3 2026'!$A$4:$I$26,7,FALSE)) | H25: =IF(ISNA(VLOOKUP($A25,'Prime Salariés T4 2026'!$A$4:$H$28,6,FALSE)),0,VLOOKUP($A25,'Prime Salariés T4 2026'!$A$4:$H$28,6,FALSE)) | I25: =IF(ISNA(VLOOKUP($A25,'Prime Salariés T4 2026'!$A$4:$H$28,7,FALSE)),0,VLOOKUP($A25,'Prime Salariés T4 2026'!$A$4:$H$28,7,FALSE)) | J25: =K25+L25 -> 365 | K25: =B25+D25+F25+H25 -> 365 | L25: =C25+E25+G25+I25 -> 0 | M25: =IF(ISNA(VLOOKUP($A26,'Prime Salariés T1 2026'!$A$3:$H$32,6,FALSE)),0,VLOOKUP($A26,'Prime Salariés T1 2026'!$A$3:$H$32,6,FALSE)) -> 474 | N25: =IF(ISNA(VLOOKUP($A26,'Prime Salariés T1 2026'!$A$3:$H$32,7,FALSE)),0,VLOOKUP($A26,'Prime Salariés T1 2026'!$A$3:$H$32,7,FALSE)) | O25: =IF(ISNA(VLOOKUP($A26,'Prime Salariés T2 2026'!$A$3:$G$22,7,FALSE)),0,VLOOKUP($A26,'Prime Salariés T2 2026'!$A$3:$G$22,7,FALSE)) | P25: =IF(ISNA(VLOOKUP($A26,'Prime Salariés T2 2026'!$A$3:$G$22,8,FALSE)),0,VLOOKUP($A26,'Prime Salariés T2 2026'!$A$3:$G$22,8,FALSE)) -> #REF!
A26: SMA | B26: =IF(ISNA(VLOOKUP($A26,'Prime Salariés T1 2026'!$A$3:$H$32,6,FALSE)),0,VLOOKUP($A26,'Prime Salariés T1 2026'!$A$3:$H$32,6,FALSE)) -> 474 | C26: =IF(ISNA(VLOOKUP($A26,'Prime Salariés T1 2026'!$A$3:$H$32,7,FALSE)),0,VLOOKUP($A26,'Prime Salariés T1 2026'!$A$3:$H$32,7,FALSE)) | D26: =IF(ISNA(VLOOKUP($A26,'Prime Salariés T2 2026'!$A$3:$G$22,6,FALSE)),0,VLOOKUP($A26,'Prime Salariés T2 2026'!$A$3:$G$22,6,FALSE)) -> 596 | E26: =IF(ISNA(VLOOKUP($A26,'Prime Salariés T2 2026'!$A$3:$G$22,7,FALSE)),0,VLOOKUP($A26,'Prime Salariés T2 2026'!$A$3:$G$22,7,FALSE)) | F26: =IF(ISNA(VLOOKUP($A26,'Prime Salariés T3 2026'!$A$4:$I$26,6,FALSE)),0,VLOOKUP($A26,'Prime Salariés T3 2026'!$A$4:$I$26,6,FALSE)) -> 0 | G26: =IF(ISNA(VLOOKUP($A26,'Prime Salariés T3 2026'!$A$4:$I$26,7,FALSE)),0,VLOOKUP($A26,'Prime Salariés T3 2026'!$A$4:$I$26,7,FALSE)) -> 0 | H26: =IF(ISNA(VLOOKUP($A26,'Prime Salariés T4 2026'!$A$4:$H$28,6,FALSE)),0,VLOOKUP($A26,'Prime Salariés T4 2026'!$A$4:$H$28,6,FALSE)) | I26: =IF(ISNA(VLOOKUP($A26,'Prime Salariés T4 2026'!$A$4:$H$28,7,FALSE)),0,VLOOKUP($A26,'Prime Salariés T4 2026'!$A$4:$H$28,7,FALSE)) | J26: =K26+L26 -> 1070 | K26: =B26+D26+F26+H26 -> 1070 | L26: =C26+E26+G26+I26 -> 0
A27: UMU | B27: =IF(ISNA(VLOOKUP($A27,'Prime Salariés T1 2026'!$A$3:$H$32,6,FALSE)),0,VLOOKUP($A27,'Prime Salariés T1 2026'!$A$3:$H$32,6,FALSE)) -> 323 | C27: =IF(ISNA(VLOOKUP($A27,'Prime Salariés T1 2026'!$A$3:$H$32,7,FALSE)),0,VLOOKUP($A27,'Prime Salariés T1 2026'!$A$3:$H$32,7,FALSE)) | D27: =IF(ISNA(VLOOKUP($A27,'Prime Salariés T2 2026'!$A$3:$G$22,6,FALSE)),0,VLOOKUP($A27,'Prime Salariés T2 2026'!$A$3:$G$22,6,FALSE)) -> 279 | E27: =IF(ISNA(VLOOKUP($A27,'Prime Salariés T2 2026'!$A$3:$G$22,7,FALSE)),0,VLOOKUP($A27,'Prime Salariés T2 2026'!$A$3:$G$22,7,FALSE)) | F27: =IF(ISNA(VLOOKUP($A27,'Prime Salariés T3 2026'!$A$4:$I$26,6,FALSE)),0,VLOOKUP($A27,'Prime Salariés T3 2026'!$A$4:$I$26,6,FALSE)) | G27: =IF(ISNA(VLOOKUP($A27,'Prime Salariés T3 2026'!$A$4:$I$26,7,FALSE)),0,VLOOKUP($A27,'Prime Salariés T3 2026'!$A$4:$I$26,7,FALSE)) | H27: =IF(ISNA(VLOOKUP($A27,'Prime Salariés T4 2026'!$A$4:$H$28,6,FALSE)),0,VLOOKUP($A27,'Prime Salariés T4 2026'!$A$4:$H$28,6,FALSE)) | I27: =IF(ISNA(VLOOKUP($A27,'Prime Salariés T4 2026'!$A$4:$H$28,7,FALSE)),0,VLOOKUP($A27,'Prime Salariés T4 2026'!$A$4:$H$28,7,FALSE)) | J27: =K27+L27 -> 602 | K27: =B27+D27+F27+H27 -> 602 | L27: =C27+E27+G27+I27 -> 0 | N27: =IF(L28<500,0,IF(L28<10000,INT(L28*$P$1/($N$1*0.7)),"formule a compléter")) -> 14 | O27: =L28-N27*(N$1*0.7)/P$1 -> 32.98087
A28: VGR | B28: =IF(ISNA(VLOOKUP($A28,'Prime Salariés T1 2026'!$A$3:$H$32,6,FALSE)),0,VLOOKUP($A28,'Prime Salariés T1 2026'!$A$3:$H$32,6,FALSE)) | C28: =IF(ISNA(VLOOKUP($A28,'Prime Salariés T1 2026'!$A$3:$H$32,7,FALSE)),0,VLOOKUP($A28,'Prime Salariés T1 2026'!$A$3:$H$32,7,FALSE)) -> 505 | D28: =IF(ISNA(VLOOKUP($A28,'Prime Salariés T2 2026'!$A$3:$G$22,6,FALSE)),0,VLOOKUP($A28,'Prime Salariés T2 2026'!$A$3:$G$22,6,FALSE)) -> 437 | E28: =IF(ISNA(VLOOKUP($A28,'Prime Salariés T2 2026'!$A$3:$G$22,7,FALSE)),0,VLOOKUP($A28,'Prime Salariés T2 2026'!$A$3:$G$22,7,FALSE)) | F28: =IF(ISNA(VLOOKUP($A28,'Prime Salariés T3 2026'!$A$4:$I$26,6,FALSE)),0,VLOOKUP($A28,'Prime Salariés T3 2026'!$A$4:$I$26,6,FALSE)) | G28: =IF(ISNA(VLOOKUP($A28,'Prime Salariés T3 2026'!$A$4:$I$26,7,FALSE)),0,VLOOKUP($A28,'Prime Salariés T3 2026'!$A$4:$I$26,7,FALSE)) | H28: =IF(ISNA(VLOOKUP($A28,'Prime Salariés T4 2026'!$A$4:$H$28,6,FALSE)),0,VLOOKUP($A28,'Prime Salariés T4 2026'!$A$4:$H$28,6,FALSE)) | I28: =IF(ISNA(VLOOKUP($A28,'Prime Salariés T4 2026'!$A$4:$H$28,7,FALSE)),0,VLOOKUP($A28,'Prime Salariés T4 2026'!$A$4:$H$28,7,FALSE)) | J28: =K28+L28 -> 942 | K28: =B28+D28+F28+H28 -> 437 | L28: =C28+E28+G28+I28 -> 505
A29: VZA | B29: =IF(ISNA(VLOOKUP($A29,'Prime Salariés T1 2026'!$A$3:$H$32,6,FALSE)),0,VLOOKUP($A29,'Prime Salariés T1 2026'!$A$3:$H$32,6,FALSE)) | C29: =IF(ISNA(VLOOKUP($A29,'Prime Salariés T1 2026'!$A$3:$H$32,7,FALSE)),0,VLOOKUP($A29,'Prime Salariés T1 2026'!$A$3:$H$32,7,FALSE)) -> 264 | D29: =IF(ISNA(VLOOKUP($A29,'Prime Salariés T2 2026'!$A$3:$G$22,6,FALSE)),0,VLOOKUP($A29,'Prime Salariés T2 2026'!$A$3:$G$22,6,FALSE)) | E29: =IF(ISNA(VLOOKUP($A29,'Prime Salariés T2 2026'!$A$3:$G$22,7,FALSE)),0,VLOOKUP($A29,'Prime Salariés T2 2026'!$A$3:$G$22,7,FALSE)) -> 522 | F29: =IF(ISNA(VLOOKUP($A29,'Prime Salariés T3 2026'!$A$4:$I$26,6,FALSE)),0,VLOOKUP($A29,'Prime Salariés T3 2026'!$A$4:$I$26,6,FALSE)) | G29: =IF(ISNA(VLOOKUP($A29,'Prime Salariés T3 2026'!$A$4:$I$26,7,FALSE)),0,VLOOKUP($A29,'Prime Salariés T3 2026'!$A$4:$I$26,7,FALSE)) | H29: =IF(ISNA(VLOOKUP($A29,'Prime Salariés T4 2026'!$A$4:$H$28,6,FALSE)),0,VLOOKUP($A29,'Prime Salariés T4 2026'!$A$4:$H$28,6,FALSE)) | I29: =IF(ISNA(VLOOKUP($A29,'Prime Salariés T4 2026'!$A$4:$H$28,7,FALSE)),0,VLOOKUP($A29,'Prime Salariés T4 2026'!$A$4:$H$28,7,FALSE)) | J29: =K29+L29 -> 786 | K29: =B29+D29+F29+H29 -> 0 | L29: =C29+E29+G29+I29 -> 786
A30: Total général | B30: =SUM(B6:B29) -> 7179 | C30: =SUM(C6:C29) -> 11035.23 | D30: =SUM(D6:D29) -> 7638.69 | E30: =SUM(E6:E29) -> 9304 | F30: =SUM(F6:F29) -> 0 | G30: =SUM(G6:G29) -> 0 | H30: =SUM(H6:H29) -> 0 | I30: =SUM(I6:I29) -> 0 | ... L30: =SUM(L6:L29) -> 20339.23

Sheet Prime Salariés T1 2026
A1: Montant des primes salariés pour le T1 2026
A3: Matricule_Perçoit_Prime | B3: Prime commerciale salarie | C3: Prime encadrement | D3: Recrutement | E3: Total général | F3: Montant demandé en salaire | G3: Montant demandé en AGA
A4: ADO | B4: 1700.28 | C4: 985.71001 | E4: =SUM(B4:D4) -> 2685.99 | H4: payé lors du STC
A5: ANO | B5: 104.31 | E5: =SUM(B5:D5) -> 104.31 | F5: 104
A6: ARA | B6: 1046.62 | E6: =SUM(B6:D6) -> 1046.62 | F6: 1047
A7: AVA | B7: 5101.23 | E7: =SUM(B7:D7) -> 5101.23 | G7: 5101.23
A8: CLM | B8: 104.31 | E8: =SUM(B8:D8) -> 104.31 | H8: payé lors du STC
A9: CME | B9: 1733.93 | C9: 1185.71 | E9: =SUM(B9:D9) -> 2919.64 | G9: 2920
A10: GBE | B10: 212.75 | C10: 796.77 | E10: =SUM(B10:D10) -> 1009.52 | G10: 1010
A11: GSA | B11: 471 | E11: =SUM(B11:D11) -> 471 | G11: 471
A12: GTA | B12: 1233.59 | E12: =SUM(B12:D12) -> 1233.59 | F12: 1234
A13: IHA | B13: 793.85 | E13: =SUM(B13:D13) -> 793.85 | F13: 794
A14: JDU | B14: 974.89 | E14: =SUM(B14:D14) -> 974.89 | F14: 975
A15: JFE | B15: 387.32 | E15: =SUM(B15:D15) -> 387.32 | F15: 387
A16: JGA | C16: 600 | E16: =SUM(B16:D16) -> 600 | F16: 600
A17: LBU | B17: 414.07 | E17: =SUM(B17:D17) -> 414.07 | F17: 414
A18: LDO | D18: 500 | E18: =SUM(B18:D18) -> 500 | H18: payé lors du STC
A19: MGU | B19: 764.27586 | E19: =SUM(B19:D19) -> 764.27586 | G19: 764
A20: MMA | C20: 600 | E20: =SUM(B20:D20) -> 600 | F20: 600
A21: NOU | B21: 226.55 | E21: =SUM(B21:D21) -> 226.55 | F21: 227
A22: SMA | B22: 474.49 | E22: =SUM(B22:D22) -> 474.49 | F22: 474
A23: UMU | B23: 322.76 | E23: =SUM(B23:D23) -> 322.76 | F23: 323
A24: VGR | B24: 504.73 | E24: =SUM(B24:D24) -> 504.73 | G24: 505
A25: VZA | B25: 264 | E25: =SUM(B25:D25) -> 264 | G25: 264
A26: Total général | B26: =SUM(B4:B25) -> 16834.956 | C26: =SUM(C4:C25) -> 4168.19 | D26: =SUM(D4:D25) -> 500 | E26: =SUM(E4:E25) -> 21503.146 | F26: =SUM(F4:F25) -> 7179 | G26: =SUM(G4:G25) -> 11035.23
A32: Annee | B32: Mois | C32: Projet | D32: Matricule_Consultant_Place | E32: Matricule_Percoit_Prime | F32: Type_Prime | G32: Nb_Jour | H32: Montant_Journalier_Brut_Salarie | I32: Montant_Mensuel_Brut_Salarie
A33: 2026 | B33: 1 | C33: Dispositif PO - TotalEnergies | D33: ABT | E33: CME | F33: Commerciale salarie | G33: 17 | H33: 0.83 | I33: 14.07
A34: 2026 | B34: 1 | C34: Dispositif PO - TotalEnergies | D34: ABT | E34: GBE | F34: Commerciale salarie | G34: 17 | H34: 0.55 | I34: 9.38
A35: 2026 | B35: 2 | C35: Dispositif PO - TotalEnergies | D35: ABT | E35: CME | F35: Commerciale salarie | G35: 14.5 | H35: 0.83 | I35: 12
A36: 2026 | B36: 2 | C36: Dispositif PO - TotalEnergies | D36: ABT | E36: GBE | F36: Commerciale salarie | G36: 14.5 | H36: 0.55 | I36: 8
A37: 2026 | B37: 3 | C37: Dispositif PO - TotalEnergies | D37: ABT | E37: CME | F37: Commerciale salarie | G37: 5 | H37: 0.83 | I37: 4.14
A38: 2026 | B38: 3 | C38: Dispositif PO - TotalEnergies | D38: ABT | E38: GBE | F38: Commerciale salarie | G38: 5 | H38: 0.55 | I38: 2.76
A39: 2026 | B39: 1 | C39: AV26 - Recette VCMS | D39: AHM | E39: AVA | F39: Commerciale salarie | G39: 16.125 | H39: 34.48 | I39: 556.03
A40: 2026 | B40: 2 | C40: AV26 - Recette VCMS | D40: AHM | E40: AVA | F40: Commerciale salarie | G40: 13 | H40: 34.48 | I40: 448.28
A41: 2026 | B41: 3 | C41: AV26 - Conception - Specification ITC | D41: AHM | E41: AVA | F41: Commerciale salarie | G41: 10 | H41: 34.48 | I41: 344.83
A42: 2026 | B42: 1 | C42: AKB - CP DATA - VW IS | D42: AKB | E42: GTA | F42: Commerciale salarie | G42: 5 | H42: 3.45 | I42: 17.24
A43: 2026 | B43: 2 | C43: AKB - CP DATA - VW IS | D43: AKB | E43: GTA | F43: Commerciale salarie | G43: 20 | H43: 3.45 | I43: 68.97
A44: 2026 | B44: 3 | C44: AKB - CP DATA - VW IS | D44: AKB | E44: GTA | F44: Commerciale salarie | G44: 22 | H44: 3.45 | I44: 75.86
... A138: 2026 | B138: 3 | C138: JGA - Train Relation Client - ENEDIS | D138: JGA | E138: CME | F138: Commerciale salarie | G138: 21 | H138: 14.34 | I138: 301.24
A139: 2026 | B139: 1 | C139: KJE - ANALYSE INCIDENTS TELEO - VW IS | D139: KJE | E139: GSA | F139: Commerciale salarie | G139: 17 | H139: 3.79
...

Sheet Prime Salariés T2 2026
A1: Montant des primes salariés pour le T2 2026
A3: Matricule_Perçoit_Prime | B3: Prime commerciale salarie | C3: Prime encadrement | D3: Recrutement | E3: Total général | F3: Montant demandé en salaire | G3: Montant demandé en AGA
A4: ARA | B4: 1028 | E4: =SUM(B4:D4) -> 1028 | F4: 1028
A5: AVA | B5: 3796.84 | E5: =SUM(B5:D5) -> 3796.84 | G5: 3797
A6: CME | B6: 1125.37 | C6: 1000 | E6: =SUM(B6:D6) -> 2125.37 | G6: 2125
A7: GBE | B7: 268.39 | C7: 1086.67 | E7: =SUM(B7:D7) -> 1355.06 | G7: 1355
A8: GSA | B8: 324 | E8: =SUM(B8:D8) -> 324 | G8: 324
A9: GTA | B9: 996.97 | E9: =SUM(B9:D9) -> 996.97 | F9: 997
A10: IHA | B10: 811 | E10: =SUM(B10:D10) -> 811 | F10: 811
A11: JDU | B11: 1271.51 | E11: =SUM(B11:D11) -> 1271.51 | F11: 1272
A12: JFE | B12: 440.56 | E12: =SUM(B12:D12) -> 440.56 | F12: 441
A13: KSA | D13: 500 | E13: =SUM(B13:D13) -> 500 | G13: 500
A14: LBU | B14: 348.69 | E14: =SUM(B14:D14) -> 348.69 | F14: 349
A15: MGU | B15: 681.03448 | E15: =SUM(B15:D15) -> 681.03448 | G15: 681
A16: MMA | C16: 400 | E16: =SUM(B16:D16) -> 400 | F16: 400
A17: MTO | B17: 890.69 | E17: =SUM(B17:D17) -> 890.69 | F17: =SUM(C17:E17) -> 890.69
A18: NOU | B18: 138.45 | E18: =SUM(B18:D18) -> 138.45 | F18: 138
A19: SMA | B19: 595.87 | E19: =SUM(B19:D19) -> 595.87 | F19: 596
A20: UMU | B20: 278.63 | E20: =SUM(B20:D20) -> 278.63 | F20: 279
A21: VGR | B21: 436.86 | E21: =SUM(B21:D21) -> 436.86 | F21: 437
A22: VZA | B22: 268.56 | C22: 253.33 | E22: =SUM(B22:D22) -> 521.89 | G22: 522
A23: Total général | B23: =SUM(B4:B22) -> 13701.424 | C23: =SUM(C4:C22) -> 2740 | D23: =SUM(D4:D22) -> 500 | E23: =SUM(E4:E22) -> 16941.424 | F23: =SUM(F4:F22) -> 7638.69 | G23: =SUM(G4:G22) -> 9304
A29: Annee | B29: Mois | C29: Projet | D29: Matricule_Consultant_Place | E29: Matricule_Percoit_Prime | F29: Type_Prime | G29: Nb_Jour | I29: Montant_Journalier_Brut_Salarie | J29: Montant_Mensuel_Brut_Salarie
A30: 2026 | B30: 4 | C30: JGA - Train Relation Client - ENEDIS | D30: JGA | E30: CME | F30: Encadrement | J30: 200
A31: 2026 | B31: 5 | C31: JGA - Train Relation Client - ENEDIS | D31: JGA | E31: CME | F31: Encadrement | J31: 200
A32: 2026 | B32: 4 | C32: SMI - Appui PO sur EV Portal / Cockpit - Total | D32: SMI | E32: CME | F32: Encadrement | J32: 200
A33: 2026 | B33: 5 | C33: SMI - Appui PO sur EV Portal / Cockpit - Total | D33: SMI | E33: CME | F33: Encadrement | J33: 200
A34: 2026 | B34: 6 | C34: SMI - Appui PO sur EV Portal / Cockpit - Total | D34: SMI | E34: CME | F34: Encadrement | J34: 200
A35: 2026 | B35: 4 | C35: MBH - PO Power & Pricing - TOTAL | D35: MBH | E35: GBE | F35: Encadrement | J35: 86.669998
A36: 2026 | B36: 5 | C36: MBH - PO Power & Pricing - TOTAL | D36: MBH | E36: GBE | F36: Encadrement | J36: 200
A37: 2026 | B37: 6 | C37: MBH - PO Power & Pricing - TOTAL | D37: MBH | E37: GBE | F37: Encadrement | J37: 200
A38: 2026 | B38: 4 | C38: JDU - Fai cloture projets - SNCF | D38: JDU | E38: GBE | F38: Encadrement | J38: 200
A39: 2026 | B39: 5 | C39: JDU - Fai cloture projets - SNCF | D39: JDU | E39: GBE | F39: Encadrement | J39: 200
A40: 2026 | B40: 6 | C40: JDU - Fai cloture projets - SNCF | D40: JDU | E40: GBE | F40: Encadrement | J40: 200
A41: 2026 | B41: 4 | C41: Dispositif PO - TotalEnergies | D41: TTR | E41: MMA | F41: encadrement | J41: 200
